Workbook

Sheet Ugotovitve
A1: Ugotovitve pregleda
A3: # | B3: Ugotovitev | C3: Podrobnosti | D3: Predlog
A4: 1 | B4: Primer z bifejem je napačen | C4: Profil Bar/bife/pub ima privzeto samo Mize, Točilnico in QR meni. Rezervacij ni med privzetimi, zato jih Extended ne doda samodejno. | D4: Popravek: »Bife dobi Mize in Točilnico v paketu Standard, QR meni pa šele v paketu Extended.«
A5: 2 | B5: Samopostrežna ponudba ni na voljo v nobenem paketu | C5: self_service je privzet pri Samopostrežni restavraciji in Hotelski gostinski ponudbi, ni pa v nobenem paketu (posPlanPolicy.test.ts: »ne oglašuje neimplementirane samopostrežne funkcije«). | D5: Odstraniti iz dokumentacije do implementacije ali označiti »v pripravi«.
A6: 3 | B6: Začasni profili v Lite/Standard izgubijo namen | C6: Dogodki, Prenosi zaloge in Kavcije/boni/žetoni so samo v Extended. V Standard dobi veselica le Kuhinjo in Točilnico. Začasna enota mora imeti nadrejeno enoto ter obdobje od–do (omejitev v bazi). | D6: Poudariti v cenikih in navodilih; razmisliti o paketu za prireditve.
A7: 4 | B7: Lite reže vse dodatne zmožnosti | C7: Lite vsebuje le osnovo: ni miz, kuhinje, točilnice – v praksi pultna blagajna. | D7: Jasno navesti v cenikih, da Lite ni primeren za strežbo pri mizi.
A8: 5 | B8: Simulacija ni privzeta nikjer | C8: simulation je v Extended, a ni v nobenem profilu niti v osnovi. | D8: Opisati kot »na voljo v Extended, vklop ročno«.

Sheet Zmožnosti
A1: Zmožnosti in najnižji paket
A2: Vir: lib/db/src/schema/company-pos-plans.ts (POS_PLAN_CAPABILITIES), stanje 8. 10. 2026. Stolpec C je vnos (modro) – spremenite paket in vsi izračuni se posodobijo.
A4: Koda | B4: Zmožnost | C4: Najnižji paket | D4: Stopnja | E4: Osnova (vse enote) | F4: Opomba
A5: checkout | B5: Blagajna | C5: Lite | D5: =IF(C5="Lite",1,IF(C5="Standard",2,IF(C5="Extended",3,99))) -> 1 | E5: Da
A6: shifts | B6: Izmene | C6: Lite | D6: =IF(C6="Lite",1,IF(C6="Standard",2,IF(C6="Extended",3,99))) -> 1 | E6: Da
A7: receipts | B7: Računi | C7: Lite | D7: =IF(C7="Lite",1,IF(C7="Standard",2,IF(C7="Extended",3,99))) -> 1 | E7: Da
A8: menu | B8: Meni | C8: Lite | D8: =IF(C8="Lite",1,IF(C8="Standard",2,IF(C8="Extended",3,99))) -> 1 | E8: Da
A9: inventory | B9: Zaloge | C9: Lite | D9: =IF(C9="Lite",1,IF(C9="Standard",2,IF(C9="Extended",3,99))) -> 1 | E9: Da
A10: statistics | B10: Statistike | C10: Lite | D10: =IF(C10="Lite",1,IF(C10="Standard",2,IF(C10="Extended",3,99))) -> 1 | E10: Da
A11: operational_reports | B11: Operativna poročila | C11: Lite | D11: =IF(C11="Lite",1,IF(C11="Standard",2,IF(C11="Extended",3,99))) -> 1 | E11: Da
A12: realization | B12: Realizacija | C12: Lite | D12: =IF(C12="Lite",1,IF(C12="Standard",2,IF(C12="Extended",3,99))) -> 1 | E12: Da
A13: journals | B13: Temeljnice | C13: Lite | D13: =IF(C13="Lite",1,IF(C13="Standard",2,IF(C13="Extended",3,99))) -> 1 | E13: Da
A14: cash_movements | B14: Blagajniški premiki | C14: Lite | D14: =IF(C14="Lite",1,IF(C14="Standard",2,IF(C14="Extended",3,99))) -> 1 | E14: Da
A15: hours | B15: Obračun ur | C15: Lite | D15: =IF(C15="Lite",1,IF(C15="Standard",2,IF(C15="Extended",3,99))) -> 1 | E15: Da
A16: settings | B16: Nastavitve | C16: Lite | D16: =IF(C16="Lite",1,IF(C16="Standard",2,IF(C16="Extended",3,99))) -> 1 | E16: Da
... A29: deposits_tokens | B29: Kavcije/boni/žetoni | C29: Extended | D29: =IF(C29="Lite",1,IF(C29="Standard",2,IF(C29="Extended",3,99))) -> 3 | E29: Ne
A30: simulation | B30: Simulacija | C30: Extended | D30: =IF(C30="Lite",1,IF(C30="Standard",2,IF(C30="Extended",3,99))) -> 3 | E30: Ne | F30: Ni v nobenem profilu – samo ročni vklop
A31: self_service | B31: Samopostrežna ponudba | C31: — | D31: =IF(C31="Lite",1,IF(C31="Standard",2,IF(C31="Extended",3,99))) -> 99 | E31: Ne | F31: Ni implementirano; ni v nobenem paketu (test posPlanPolicy)

Sheet Profili
A1: Privzete zmožnosti po vrsti lokala (1 = privzeto vključeno)
A2: Vir: lib/db/src/schema/pos/enote.ts (HOSPITALITY_PROFILE_DEFAULTS). Celice 1/0 so vnos (modro).
A4: Koda | B4: Vrsta | C4: Način strežbe | D4: service_mode | E4: Začasna | F4: Blagajna | G4: Izmene | H4: Računi | I4: Meni | J4: Zaloge | K4: Statistike | L4: Operativna poročila | M4: Realizacija | N4: Temeljnice | O4: Blagajniški premiki | P4: Obračun ur | Q4: Nastavitve | R4: Mize | S4: Kuhinja | T4: Točilnica | U4: Pripravljena hrana | V4: Odpadki | W4: Telefonska naročila | X4: Rezervacije | Y4: Dostava | Z4: QR meni | AA4: Večhodni meniji | AB4: Dogodki | AC4: Prenosi zaloge | AD4: Kavcije/boni/žetoni | AE4: Simulacija | AF4: Samopostrežna ponudba
A5: restaurant | B5: Restavracija | C5: pri mizi | D5: table_service | E5: Ne | F5: 1 | G5: 1 | H5: 1 | I5: 1 | J5: 1 | K5: 1 | L5: 1 | M5: 1 | N5: 1 | O5: 1 | P5: 1 | Q5: 1 | R5: 1 | S5: 1 | T5: 1 | U5: 1 | V5: 1 | W5: 1 | X5: 1 | Y5: 1 | Z5: 1 | AA5: 0 | AB5: 0 | AC5: 0 | AD5: 0 | AE5: 0 | AF5: 0
A6: inn | B6: Gostilna / gostišče | C6: pri mizi | D6: table_service | E6: Ne | F6: 1 | G6: 1 | H6: 1 | I6: 1 | J6: 1 | K6: 1 | L6: 1 | M6: 1 | N6: 1 | O6: 1 | P6: 1 | Q6: 1 | R6: 1 | S6: 1 | T6: 1 | U6: 1 | V6: 1 | W6: 0 | X6: 1 | Y6: 1 | Z6: 1 | AA6: 0 | AB6: 1 | AC6: 0 | AD6: 0 | AE6: 0 | AF6: 0
A7: fine_dining | B7: Fine dining | C7: pri mizi | D7: table_service | E7: Ne | F7: 1 | G7: 1 | H7: 1 | I7: 1 | J7: 1 | K7: 1 | L7: 1 | M7: 1 | N7: 1 | O7: 1 | P7: 1 | Q7: 1 | R7: 1 | S7: 1 | T7: 1 | U7: 1 | V7: 1 | W7: 0 | X7: 1 | Y7: 0 | Z7: 0 | AA7: 1 | AB7: 1 | AC7: 0 | AD7: 0 | AE7: 0 | AF7: 0
A8: self_service | B8: Samopostrežna restavracija | C8: samopostrežba | D8: self_service | E8: Ne | F8: 1 | G8: 1 | H8: 1 | I8: 1 | J8: 1 | K8: 1 | L8: 1 | M8: 1 | N8: 1 | O8: 1 | P8: 1 | Q8: 1 | R8: 0 | S8: 1 | T8: 0 | U8: 1 | V8: 1 | W8: 0 | X8: 0 | Y8: 0 | Z8: 0 | AA8: 0 | AB8: 0 | AC8: 0 | AD8: 0 | AE8: 0 | AF8: 1
A9: fast_food | B9: Hitra prehrana / kiosk | C9: pult | D9: counter | E9: Ne | F9: 1 | G9: 1 | H9: 1 | I9: 1 | J9: 1 | K9: 1 | L9: 1 | M9: 1 | N9: 1 | O9: 1 | P9: 1 | Q9: 1 | R9: 0 | S9: 1 | T9: 0 | U9: 1 | V9: 0 | W9: 1 | X9: 0 | Y9: 1 | Z9: 1 | AA9: 0 | AB9: 0 | AC9: 0 | AD9: 0 | AE9: 0 | AF9: 0
A10: bar | B10: Bar / bife / pub | C10: kombinirano | D10: mixed | E10: Ne | F10: 1 | G10: 1 | H10: 1 | I10: 1 | J10: 1 | K10: 1 | L10: 1 | M10: 1 | N10: 1 | O10: 1 | P10: 1 | Q10: 1 | R10: 1 | S10: 0 | T10: 1 | U10: 0 | V10: 0 | W10: 0 | X10: 0 | Y10: 0 | Z10: 1 | AA10: 0 | AB10: 0 | AC10: 0 | AD10: 0 | AE10: 0 | AF10: 0
A11: cafe_pastry | B11: Kavarna / slaščičarna | C11: pri mizi | D11: table_service | E11: Ne | F11: 1 | G11: 1 | H11: 1 | I11: 1 | J11: 1 | K11: 1 | L11: 1 | M11: 1 | N11: 1 | O11: 1 | P11: 1 | Q11: 1 | R11: 1 | S11: 0 | T11: 1 | U11: 1 | V11: 0 | W11: 1 | X11: 0 | Y11: 0 | Z11: 1 | AA11: 0 | AB11: 0 | AC11: 0 | AD11: 0 | AE11: 0 | AF11: 0
A12: tourist_farm | B12: Turistična kmetija / osmica | C12: pri mizi | D12: table_service | E12: Ne | F12: 1 | G12: 1 | H12: 1 | I12: 1 | J12: 1 | K12: 1 | L12: 1 | M12: 1 | N12: 1 | O12: 1 | P12: 1 | Q12: 1 | R12: 1 | S12: 1 | T12: 1 | U12: 1 | V12: 0 | W12: 0 | X12: 1 | Y12: 0 | Z12: 0 | AA12: 0 | AB12: 1 | AC12: 0 | AD12: 0 | AE12: 0 | AF12: 0
A13: festival_society | B13: Društvo / veselica | C13: prireditev | D13: mobile_event | E13: Da | F13: 1 | G13: 1 | H13: 1 | I13: 1 | J13: 1 | K13: 1 | L13: 1 | M13: 1 | N13: 1 | O13: 1 | P13: 1 | Q13: 1 | R13: 0 | S13: 1 | T13: 1 | U13: 0 | V13: 0 | W13: 0 | X13: 0 | Y13: 0 | Z13: 0 | AA13: 0 | AB13: 1 | AC13: 1 | AD13: 1 | AE13: 0 | AF13: 0
A14: event_stall | B14: Prireditvena stojnica | C14: prireditev | D14: mobile_event | E14: Da | F14: 1 | G14: 1 | H14: 1 | I14: 1 | J14: 1 | K14: 1 | L14: 1 | M14: 1 | N14: 1 | O14: 1 | P14: 1 | Q14: 1 | R14: 0 | S14: 1 | T14: 1 | U14: 0 | V14: 0 | W14: 0 | X14: 0 | Y14: 0 | Z14: 0 | AA14: 0 | AB14: 1 | AC14: 1 | AD14: 1 | AE14: 0 | AF14: 0
A15: catering_celebrations | B15: Pogostitve in slavja | C15: catering | D15: catering | E15: Ne | F15: 1 | G15: 1 | H15: 1 | I15: 1 | J15: 1 | K15: 1 | L15: 1 | M15: 1 | N15: 1 | O15: 1 | P15: 1 | Q15: 1 | R15: 1 | S15: 1 | T15: 1 | U15: 0 | V15: 0 | W15: 0 | X15: 1 | Y15: 0 | Z15: 0 | AA15: 1 | AB15: 1 | AC15: 1 | AD15: 0 | AE15: 0 | AF15: 0
A16: food_truck | B16: Food truck / prikolica / kombi | C16: prireditev | D16: mobile_event | E16: Da | F16: 1 | G16: 1 | H16: 1 | I16: 1 | J16: 1 | K16: 1 | L16: 1 | M16: 1 | N16: 1 | O16: 1 | P16: 1 | Q16: 1 | R16: 0 | S16: 1 | T16: 0 | U16: 1 | V16: 0 | W16: 0 | X16: 0 | Y16: 1 | Z16: 0 | AA16: 0 | AB16: 1 | AC16: 1 | AD16: 0 | AE16: 0 | AF16: 0
A17: hotel_food_service | B17: Hotelska gostinska ponudba | C17: kombinirano | D17: mixed | E17: Ne | F17: 1 | G17: 1 | H17: 1 | I17: 1 | J17: 1 | K17: 1 | L17: 1 | M17: 1 | N17: 1 | O17: 1 | P17: 1 | Q17: 1 | R17: 1 | S17: 1 | T17: 1 | U17: 1 | V17: 1 | W17: 0 | X17: 1 | Y17: 0 | Z17: 0 | AA17: 0 | AB17: 0 | AC17: 0 | AD17: 0 | AE17: 0 | AF17: 1

Sheet Po paketih
A1: Dejanske zmožnosti po paketu
A2: Izračun: zmožnost iz profila (Profili) × najnižji paket (Zmožnosti). Osnova je izpuščena, ker je enaka za vse.
A4: Vrsta | B4: Standard doda | C4: Extended doda še | D4: Ni v nobenem paketu | E4: Št. v Standard | F4: Št. v Extended | G4: Št. nedosegljivih
A5: =Profili!B5 -> Restavracija | B5: =_xlfn.TEXTJOIN(", ",TRUE(),IF(AND(Profili!R5=1,Zmožnosti!$D$17=2),"Mize",""),IF(AND(Profili!S5=1,Zmožnosti!$D$18=2),"Kuhinja",""),IF(AND(Profili!T5=1,Zmožnosti!$D$19=2),"Točilnica",""),IF(AND(Profili!U5=1,Zmožnosti!$D$20=2),"Pripravljena hrana",""),IF(AND(Profili!V5=1,Zmožnosti!$D$21=2),"Odpadki",""),IF(AND(Profili!W5=1,Zmožnosti!$D$22=2),"Telefonska naročila",""),IF(AND(Profili!X5=1,Zmožnosti!$D$23=2),"Rezervacije",""),IF(AND(Profili!Y5=1,Zmožnosti!$D$24=2),"Dostava",""),IF(AND(Profili!Z5=1,Zmožnosti!$D$25=2),"QR meni",""),IF(AND(Profili!AA5=1,Zmožnosti!$D$26=2),"Večhodni meniji",""),IF(AND(Profili!AB5=1,Zmožnosti!$D$27=2),"Dogodki",""),IF(AND(Profili!AC5=1,Zmožnosti!$D$28=2),"Prenosi zaloge",""),IF(AND(Profili!AD5=1,Zmožnosti!$D$29=2),"Kavcije/boni/žetoni",""),IF(AND(Profili!AE5=1,Zmožnosti!$D$30=2),"Simulacija",""),IF(AND(Profili!AF5=1,Zmožnosti!$D$31=2),"Samopostrežna ponudba","")) -> Mize, Kuhinja, Točilnica, Pripravljena hrana, Odpadki, Telefonska naročila | C5: =_xlfn.TEXTJOIN(", ",TRUE(),IF(AND(Profili!R5=1,Zmožnosti!$D$17=3),"Mize",""),IF(AND(Profili!S5=1,Zmožnosti!$D$18=3),"Kuhinja",""),IF(AND(Profili!T5=1,Zmožnosti!$D$19=3),"Točilnica",""),IF(AND(Profili!U5=1,Zmožnosti!$D$20=3),"Pripravljena hrana",""),IF(AND(Profili!V5=1,Zmožnosti!$D$21=3),"Odpadki",""),IF(AND(Profili!W5=1,Zmožnosti!$D$22=3),"Telefonska naročila",""),IF(AND(Profili!X5=1,Zmožnosti!$D$23=3),"Rezervacije",""),IF(AND(Profili!Y5=1,Zmožnosti!$D$24=3),"Dostava",""),IF(AND(Profili!Z5=1,Zmožnosti!$D$25=3),"QR meni",""),IF(AND(Profili!AA5=1,Zmožnosti!$D$26=3),"Večhodni meniji",""),IF(AND(Profili!AB5=1,Zmožnosti!$D$27=3),"Dogodki",""),IF(AND(Profili!AC5=1,Zmožnosti!$D$28=3),"Prenosi zaloge",""),IF(AND(Profili!AD5=1,Zmožnosti!$D$29=3),"Kavcije/boni/žetoni",""),IF(AND(Profili!AE5=1,Zmožnosti!$D$30=3),"Simulacija",""),IF(AND(Profili!AF5=1,Zmožnosti!$D$31=3),"Samopostrežna ponudba","")) -> Rezervacije, Dostava, QR meni | D5: =_xlfn.TEXTJOIN(", ",TRUE(),IF(AND(Profili!R5=1,Zmožnosti!$D$17=99),"Mize",""),IF(AND(Profili!S5=1,Zmožnosti!$D$18=99),"Kuhinja",""),IF(AND(Profili!T5=1,Zmožnosti!$D$19=99),"Točilnica",""),IF(AND(Profili!U5=1,Zmožnosti!$D$20=99),"Pripravljena hrana",""),IF(AND(Profili!V5=1,Zmožnosti!$D$21=99),"Odpadki",""),IF(AND(Profili!W5=1,Zmožnosti!$D$22=99),"Telefonska naročila",""),IF(AND(Profili!X5=1,Zmožnosti!$D$23=99),"Rezervacije",""),IF(AND(Profili!Y5=1,Zmožnosti!$D$24=99),"Dostava",""),IF(AND(Profili!Z5=1,Zmožnosti!$D$25=99),"QR meni",""),IF(AND(Profili!AA5=1,Zmožnosti!$D$26=99),"Večhodni meniji",""),IF(AND(Profili!AB5=1,Zmožnosti!$D$27=99),"Dogodki",""),IF(AND(Profili!AC5=1,Zmožnosti!$D$28=99),"Prenosi zaloge",""),IF(AND(Profili!AD5=1,Zmožnosti!$D$29=99),"Kavcije/boni/žetoni",""),IF(AND(Profili!AE5=1,Zmožnosti!$D$30=99),"Simulacija",""),IF(AND(Profili!AF5=1,Zmožnosti!$D$31=99),"Samopostrežna ponudba","")) | E5: =(Profili!R5=1)*(Zmožnosti!$D$17=2)+(Profili!S5=1)*(Zmožnosti!$D$18=2)+(Profili!T5=1)*(Zmožnosti!$D$19=2)+(Profili!U5=1)*(Zmožnosti!$D$20=2)+(Profili!V5=1)*(Zmožnosti!$D$21=2)+(Profili!W5=1)*(Zmožnosti!$D$22=2)+(Profili!X5=1)*(Zmožnosti!$D$23=2)+(Profili!Y5=1)*(Zmožnosti!$D$24=2)+(Profili!Z5=1)*(Zmožnosti!$D$25=2)+(Profili!AA5=1)*(Zmožnosti!$D$26=2)+(Profili!AB5=1)*(Zmožnosti!$D$27=2)+(Profili!AC5=1)*(Zmožnosti!$D$28=2)+(Profili!AD5=1)*(Zmožnosti!$D$29=2)+(Profili!AE5=1)*(Zmožnosti!$D$30=2)+(Profili!AF5=1)*(Zmožnosti!$D$31=2) -> 6 | F5: =(Profili!R5=1)*(Zmožnosti!$D$17=3)+(Profili!S5=1)*(Zmožnosti!$D$18=3)+(Profili!T5=1)*(Zmožnosti!$D$19=3)+(Profili!U5=1)*(Zmožnosti!$D$20=3)+(Profili!V5=1)*(Zmožnosti!$D$21=3)+(Profili!W5=1)*(Zmožnosti!$D$22=3)+(Profili!X5=1)*(Zmožnosti!$D$23=3)+(Profili!Y5=1)*(Zmožnosti!$D$24=3)+(Profili!Z5=1)*(Zmožnosti!$D$25=3)+(Profili!AA5=1)*(Zmožnosti!$D$26=3)+(Profili!AB5=1)*(Zmožnosti!$D$27=3)+(Profili!AC5=1)*(Zmožnosti!$D$28=3)+(Profili!AD5=1)*(Zmožnosti!$D$29=3)+(Profili!AE5=1)*(Zmožnosti!$D$30=3)+(Profili!AF5=1)*(Zmožnosti!$D$31=3) -> 3 | G5: =(Profili!R5=1)*(Zmožnosti!$D$17=99)+(Profili!S5=1)*(Zmožnosti!$D$18=99)+(Profili!T5=1)*(Zmožnosti!$D$19=99)+(Profili!U5=1)*(Zmožnosti!$D$20=99)+(Profili!V5=1)*(Zmožnosti!$D$21=99)+(Profili!W5=1)*(Zmožnosti!$D$22=99)+(Profili!X5=1)*(Zmožnosti!$D$23=99)+(Profili!Y5=1)*(Zmožnosti!$D$24=99)+(Profili!Z5=1)*(Zmožnosti!$D$25=99)+(Profili!AA5=1)*(Zmožnosti!$D$26=99)+(Profili!AB5=1)*(Zmožnosti!$D$27=99)+(Profili!AC5=1)*(Zmožnosti!$D$28=99)+(Profili!AD5=1)*(Zmožnosti!$D$29=99)+(Profili!AE5=1)*(Zmožnosti!$D$30=99)+(Profili!AF5=1)*(Zmožnosti!$D$31=99) -> 0
A6: =Profili!B6 -> Gostilna / gostišče | B6: =_xlfn.TEXTJOIN(", ",TRUE(),IF(AND(Profili!R6=1,Zmožnosti!$D$17=2),"Mize",""),IF(AND(Profili!S6=1,Zmožnosti!$D$18=2),"Kuhinja",""),IF(AND(Profili!T6=1,Zmožnosti!$D$19=2),"Točilnica",""),IF(AND(Profili!U6=1,Zmožnosti!$D$20=2),"Pripravljena hrana",""),IF(AND(Profili!V6=1,Zmožnosti!$D$21=2),"Odpadki",""),IF(AND(Profili!W6=1,Zmožnosti!$D$22=2),"Telefonska naročila",""),IF(AND(Profili!X6=1,Zmožnosti!$D$23=2),"Rezervacije",""),IF(AND(Profili!Y6=1,Zmožnosti!$D$24=2),"Dostava",""),IF(AND(Profili!Z6=1,Zmožnosti!$D$25=2),"QR meni",""),IF(AND(Profili!AA6=1,Zmožnosti!$D$26=2),"Večhodni meniji",""),IF(AND(Profili!AB6=1,Zmožnosti!$D$27=2),"Dogodki",""),IF(AND(Profili!AC6=1,Zmožnosti!$D$28=2),"Prenosi zaloge",""),IF(AND(Profili!AD6=1,Zmožnosti!$D$29=2),"Kavcije/boni/žetoni",""),IF(AND(Profili!AE6=1,Zmožnosti!$D$30=2),"Simulacija",""),IF(AND(Profili!AF6=1,Zmožnosti!$D$31=2),"Samopostrežna ponudba","")) -> Mize, Kuhinja, Točilnica, Pripravljena hrana, Odpadki | C6: =_xlfn.TEXTJOIN(", ",TRUE(),IF(AND(Profili!R6=1,Zmožnosti!$D$17=3),"Mize",""),IF(AND(Profili!S6=1,Zmožnosti!$D$18=3),"Kuhinja",""),IF(AND(Profili!T6=1,Zmožnosti!$D$19=3),"Točilnica",""),IF(AND(Profili!U6=1,Zmožnosti!$D$20=3),"Pripravljena hrana",""),IF(AND(Profili!V6=1,Zmožnosti!$D$21=3),"Odpadki",""),IF(AND(Profili!W6=1,Zmožnosti!$D$22=3),"Telefonska naročila",""),IF(AND(Profili!X6=1,Zmožnosti!$D$23=3),"Rezervacije",""),IF(AND(Profili!Y6=1,Zmožnosti!$D$24=3),"Dostava",""),IF(AND(Profili!Z6=1,Zmožnosti!$D$25=3),"QR meni",""),IF(AND(Profili!AA6=1,Zmožnosti!$D$26=3),"Večhodni meniji",""),IF(AND(Profili!AB6=1,Zmožnosti!$D$27=3),"Dogodki",""),IF(AND(Profili!AC6=1,Zmožnosti!$D$28=3),"Prenosi zaloge",""),IF(AND(Profili!AD6=1,Zmožnosti!$D$29=3),"Kavcije/boni/žetoni",""),IF(AND(Profili!AE6=1,Zmožnosti!$D$30=3),"Simulacija",""),IF(AND(Profili!AF6=1,Zmožnosti!$D$31=3),"Samopostrežna ponudba","")) -> Rezervacije, Dostava, QR meni, Dogodki | D6: =_xlfn.TEXTJOIN(", ",TRUE(),IF(AND(Profili!R6=1,Zmožnosti!$D$17=99),"Mize",""),IF(AND(Profili!S6=1,Zmožnosti!$D$18=99),"Kuhinja",""),IF(AND(Profili!T6=1,Zmožnosti!$D$19=99),"Točilnica",""),IF(AND(Profili!U6=1,Zmožnosti!$D$20=99),"Pripravljena hrana",""),IF(AND(Profili!V6=1,Zmožnosti!$D$21=99),"Odpadki",""),IF(AND(Profili!W6=1,Zmožnosti!$D$22=99),"Telefonska naročila",""),IF(AND(Profili!X6=1,Zmožnosti!$D$23=99),"Rezervacije",""),IF(AND(Profili!Y6=1,Zmožnosti!$D$24=99),"Dostava",""),IF(AND(Profili!Z6=1,Zmožnosti!$D$25=99),"QR meni",""),IF(AND(Profili!AA6=1,Zmožnosti!$D$26=99),"Večhodni meniji",""),IF(AND(Profili!AB6=1,Zmožnosti!$D$27=99),"Dogodki",""),IF(AND(Profili!AC6=1,Zmožnosti!$D$28=99),"Prenosi zaloge",""),IF(AND(Profili!AD6=1,Zmožnosti!$D$29=99),"Kavcije/boni/žetoni",""),IF(AND(Profili!AE6=1,Zmožnosti!$D$30=99),"Simulacija",""),IF(AND(Profili!AF6=1,Zmožnosti!$D$31=99),"Samopostrežna ponudba","")) | E6: =(Profili!R6=1)*(Zmožnosti!$D$17=2)+(Profili!S6=1)*(Zmožnosti!$D$18=2)+(Profili!T6=1)*(Zmožnosti!$D$19=2)+(Profili!U6=1)*(Zmožnosti!$D$20=2)+(Profili!V6=1)*(Zmožnosti!$D$21=2)+(Profili!W6=1)*(Zmožnosti!$D$22=2)+(Profili!X6=1)*(Zmožnosti!$D$23=2)+(Profili!Y6=1)*(Zmožnosti!$D$24=2)+(Profili!Z6=1)*(Zmožnosti!$D$25=2)+(Profili!AA6=1)*(Zmožnosti!$D$26=2)+(Profili!AB6=1)*(Zmožnosti!$D$27=2)+(Profili!AC6=1)*(Zmožnosti!$D$28=2)+(Profili!AD6=1)*(Zmožnosti!$D$29=2)+(Profili!AE6=1)*(Zmožnosti!$D$30=2)+(Profili!AF6=1)*(Zmožnosti!$D$31=2) -> 5 | F6: =(Profili!R6=1)*(Zmožnosti!$D$17=3)+(Profili!S6=1)*(Zmožnosti!$D$18=3)+(Profili!T6=1)*(Zmožnosti!$D$19=3)+(Profili!U6=1)*(Zmožnosti!$D$20=3)+(Profili!V6=1)*(Zmožnosti!$D$21=3)+(Profili!W6=1)*(Zmožnosti!$D$22=3)+(Profili!X6=1)*(Zmožnosti!$D$23=3)+(Profili!Y6=1)*(Zmožnosti!$D$24=3)+(Profili!Z6=1)*(Zmožnosti!$D$25=3)+(Profili!AA6=1)*(Zmožnosti!$D$26=3)+(Profili!AB6=1)*(Zmožnosti!$D$27=3)+(Profili!AC6=1)*(Zmožnosti!$D$28=3)+(Profili!AD6=1)*(Zmožnosti!$D$29=3)+(Profili!AE6=1)*(Zmožnosti!$D$30=3)+(Profili!AF6=1)*(Zmožnosti!$D$31=3) -> 4 | G6: =(Profili!R6=1)*(Zmožnosti!$D$17=99)+(Profili!S6=1)*(Zmožnosti!$D$18=99)+(Profili!T6=1)*(Zmožnosti!$D$19=99)+(Profili!U6=1)*(Zmožnosti!$D$20=99)+(Profili!V6=1)*(Zmožnosti!$D$21=99)+(Profili!W6=1)*(Zmožnosti!$D$22=99)+(Profili!X6=1)*(Zmožnosti!$D$23=99)+(Profili!Y6=1)*(Zmožnosti!$D$24=99)+(Profili!Z6=1)*(Zmožnosti!$D$25=99)+(Profili!AA6=1)*(Zmožnosti!$D$26=99)+(Profili!AB6=1)*(Zmožnosti!$D$27=99)+(Profili!AC6=1)*(Zmožnosti!$D$28=99)+(Profili!AD6=1)*(Zmožnosti!$D$29=99)+(Profili!AE6=1)*(Zmožnosti!$D$30=99)+(Profili!AF6=1)*(Zmožnosti!$D$31=99) -> 0
A7: =Profili!B7 -> Fine dining | B7: =_xlfn.TEXTJOIN(", ",TRUE(),IF(AND(Profili!R7=1,Zmožnosti!$D$17=2),"Mize",""),IF(AND(Profili!S7=1,Zmožnosti!$D$18=2),"Kuhinja",""),IF(AND(Profili!T7=1,Zmožnosti!$D$19=2),"Točilnica",""),IF(AND(Profili!U7=1,Zmožnosti!$D$20=2),"Pripravljena hrana",""),IF(AND(Profili!V7=1,Zmožnosti!$D$21=2),"Odpadki",""),IF(AND(Profili!W7=1,Zmožnosti!$D$22=2),"Telefonska naročila",""),IF(AND(Profili!X7=1,Zmožnosti!$D$23=2),"Rezervacije",""),IF(AND(Profili!Y7=1,Zmožnosti!$D$24=2),"Dostava",""),IF(AND(Profili!Z7=1,Zmožnosti!$D$25=2),"QR meni",""),IF(AND(Profili!AA7=1,Zmožnosti!$D$26=2),"Večhodni meniji",""),IF(AND(Profili!AB7=1,Zmožnosti!$D$27=2),"Dogodki",""),IF(AND(Profili!AC7=1,Zmožnosti!$D$28=2),"Prenosi zaloge",""),IF(AND(Profili!AD7=1,Zmožnosti!$D$29=2),"Kavcije/boni/žetoni",""),IF(AND(Profili!AE7=1,Zmožnosti!$D$30=2),"Simulacija",""),IF(AND(Profili!AF7=1,Zmožnosti!$D$31=2),"Samopostrežna ponudba","")) -> Mize, Kuhinja, Točilnica, Pripravljena hrana, Odpadki | C7: =_xlfn.TEXTJOIN(", ",TRUE(),IF(AND(Profili!R7=1,Zmožnosti!$D$17=3),"Mize",""),IF(AND(Profili!S7=1,Zmožnosti!$D$18=3),"Kuhinja",""),IF(AND(Profili!T7=1,Zmožnosti!$D$19=3),"Točilnica",""),IF(AND(Profili!U7=1,Zmožnosti!$D$20=3),"Pripravljena hrana",""),IF(AND(Profili!V7=1,Zmožnosti!$D$21=3),"Odpadki",""),IF(AND(Profili!W7=1,Zmožnosti!$D$22=3),"Telefonska naročila",""),IF(AND(Profili!X7=1,Zmožnosti!$D$23=3),"Rezervacije",""),IF(AND(Profili!Y7=1,Zmožnosti!$D$24=3),"Dostava",""),IF(AND(Profili!Z7=1,Zmožnosti!$D$25=3),"QR meni",""),IF(AND(Profili!AA7=1,Zmožnosti!$D$26=3),"Večhodni meniji",""),IF(AND(Profili!AB7=1,Zmožnosti!$D$27=3),"Dogodki",""),IF(AND(Profili!AC7=1,Zmožnosti!$D$28=3),"Prenosi zaloge",""),IF(AND(Profili!AD7=1,Zmožnosti!$D$29=3),"Kavcije/boni/žetoni",""),IF(AND(Profili!AE7=1,Zmožnosti!$D$30=3),"Simulacija",""),IF(AND(Profili!AF7=1,Zmožnosti!$D$31=3),"Samopostrežna ponudba","")) -> Rezervacije, Večhodni meniji, Dogodki | D7: =_xlfn.TEXTJOIN(", ",TRUE(),IF(AND(Profili!R7=1,Zmožnosti!$D$17=99),"Mize",""),IF(AND(Profili!S7=1,Zmožnosti!$D$18=99),"Kuhinja",""),IF(AND(Profili!T7=1,Zmožnosti!$D$19=99),"Točilnica",""),IF(AND(Profili!U7=1,Zmožnosti!$D$20=99),"Pripravljena hrana",""),IF(AND(Profili!V7=1,Zmožnosti!$D$21=99),"Odpadki",""),IF(AND(Profili!W7=1,Zmožnosti!$D$22=99),"Telefonska naročila",""),IF(AND(Profili!X7=1,Zmožnosti!$D$23=99),"Rezervacije",""),IF(AND(Profili!Y7=1,Zmožnosti!$D$24=99),"Dostava",""),IF(AND(Profili!Z7=1,Zmožnosti!$D$25=99),"QR meni",""),IF(AND(Profili!AA7=1,Zmožnosti!$D$26=99),"Večhodni meniji",""),IF(AND(Profili!AB7=1,Zmožnosti!$D$27=99),"Dogodki",""),IF(AND(Profili!AC7=1,Zmožnosti!$D$28=99),"Prenosi zaloge",""),IF(AND(Profili!AD7=1,Zmožnosti!$D$29=99),"Kavcije/boni/žetoni",""),IF(AND(Profili!AE7=1,Zmožnosti!$D$30=99),"Simulacija",""),IF(AND(Profili!AF7=1,Zmožnosti!$D$31=99),"Samopostrežna ponudba","")) | E7: =(Profili!R7=1)*(Zmožnosti!$D$17=2)+(Profili!S7=1)*(Zmožnosti!$D$18=2)+(Profili!T7=1)*(Zmožnosti!$D$19=2)+(Profili!U7=1)*(Zmožnosti!$D$20=2)+(Profili!V7=1)*(Zmožnosti!$D$21=2)+(Profili!W7=1)*(Zmožnosti!$D$22=2)+(Profili!X7=1)*(Zmožnosti!$D$23=2)+(Profili!Y7=1)*(Zmožnosti!$D$24=2)+(Profili!Z7=1)*(Zmožnosti!$D$25=2)+(Profili!AA7=1)*(Zmožnosti!$D$26=2)+(Profili!AB7=1)*(Zmožnosti!$D$27=2)+(Profili!AC7=1)*(Zmožnosti!$D$28=2)+(Profili!AD7=1)*(Zmožnosti!$D$29=2)+(Profili!AE7=1)*(Zmožnosti!$D$30=2)+(Profili!AF7=1)*(Zmožnosti!$D$31=2) -> 5 | F7: =(Profili!R7=1)*(Zmožnosti!$D$17=3)+(Profili!S7=1)*(Zmožnosti!$D$18=3)+(Profili!T7=1)*(Zmožnosti!$D$19=3)+(Profili!U7=1)*(Zmožnosti!$D$20=3)+(Profili!V7=1)*(Zmožnosti!$D$21=3)+(Profili!W7=1)*(Zmožnosti!$D$22=3)+(Profili!X7=1)*(Zmožnosti!$D$23=3)+(Profili!Y7=1)*(Zmožnosti!$D$24=3)+(Profili!Z7=1)*(Zmožnosti!$D$25=3)+(Profili!AA7=1)*(Zmožnosti!$D$26=3)+(Profili!AB7=1)*(Zmožnosti!$D$27=3)+(Profili!AC7=1)*(Zmožnosti!$D$28=3)+(Profili!AD7=1)*(Zmožnosti!$D$29=3)+(Profili!AE7=1)*(Zmožnosti!$D$30=3)+(Profili!AF7=1)*(Zmožnosti!$D$31=3) -> 3 | G7: =(Profili!R7=1)*(Zmožnosti!$D$17=99)+(Profili!S7=1)*(Zmožnosti!$D$18=99)+(Profili!T7=1)*(Zmožnosti!$D$19=99)+(Profili!U7=1)*(Zmožnosti!$D$20=99)+(Profili!V7=1)*(Zmožnosti!$D$21=99)+(Profili!W7=1)*(Zmožnosti!$D$22=99)+(Profili!X7=1)*(Zmožnosti!$D$23=99)+(Profili!Y7=1)*(Zmožnosti!$D$24=99)+(Profili!Z7=1)*(Zmožnosti!$D$25=99)+(Profili!AA7=1)*(Zmožnosti!$D$26=99)+(Profili!AB7=1)*(Zmožnosti!$D$27=99)+(Profili!AC7=1)*(Zmožnosti!$D$28=99)+(Profili!AD7=1)*(Zmožnosti!$D$29=99)+(Profili!AE7=1)*(Zmožnosti!$D$30=99)+(Profili!AF7=1)*(Zmožnosti!$D$31=99) -> 0
A8: =Profili!B8 -> Samopostrežna restavracija | B8: =_xlfn.TEXTJOIN(", ",TRUE(),IF(AND(Profili!R8=1,Zmožnosti!$D$17=2),"Mize",""),IF(AND(Profili!S8=1,Zmožnosti!$D$18=2),"Kuhinja",""),IF(AND(Profili!T8=1,Zmožnosti!$D$19=2),"Točilnica",""),IF(AND(Profili!U8=1,Zmožnosti!$D$20=2),"Pripravljena hrana",""),IF(AND(Profili!V8=1,Zmožnosti!$D$21=2),"Odpadki",""),IF(AND(Profili!W8=1,Zmožnosti!$D$22=2),"Telefonska naročila",""),IF(AND(Profili!X8=1,Zmožnosti!$D$23=2),"Rezervacije",""),IF(AND(Profili!Y8=1,Zmožnosti!$D$24=2),"Dostava",""),IF(AND(Profili!Z8=1,Zmožnosti!$D$25=2),"QR meni",""),IF(AND(Profili!AA8=1,Zmožnosti!$D$26=2),"Večhodni meniji",""),IF(AND(Profili!AB8=1,Zmožnosti!$D$27=2),"Dogodki",""),IF(AND(Profili!AC8=1,Zmožnosti!$D$28=2),"Prenosi zaloge",""),IF(AND(Profili!AD8=1,Zmožnosti!$D$29=2),"Kavcije/boni/žetoni",""),IF(AND(Profili!AE8=1,Zmožnosti!$D$30=2),"Simulacija",""),IF(AND(Profili!AF8=1,Zmožnosti!$D$31=2),"Samopostrežna ponudba","")) -> Kuhinja, Pripravljena hrana, Odpadki | C8: =_xlfn.TEXTJOIN(", ",TRUE(),IF(AND(Profili!R8=1,Zmožnosti!$D$17=3),"Mize",""),IF(AND(Profili!S8=1,Zmožnosti!$D$18=3),"Kuhinja",""),IF(AND(Profili!T8=1,Zmožnosti!$D$19=3),"Točilnica",""),IF(AND(Profili!U8=1,Zmožnosti!$D$20=3),"Pripravljena hrana",""),IF(AND(Profili!V8=1,Zmožnosti!$D$21=3),"Odpadki",""),IF(AND(Profili!W8=1,Zmožnosti!$D$22=3),"Telefonska naročila",""),IF(AND(Profili!X8=1,Zmožnosti!$D$23=3),"Rezervacije",""),IF(AND(Profili!Y8=1,Zmožnosti!$D$24=3),"Dostava",""),IF(AND(Profili!Z8=1,Zmožnosti!$D$25=3),"QR meni",""),IF(AND(Profili!AA8=1,Zmožnosti!$D$26=3),"Večhodni meniji",""),IF(AND(Profili!AB8=1,Zmožnosti!$D$27=3),"Dogodki",""),IF(AND(Profili!AC8=1,Zmožnosti!$D$28=3),"Prenosi zaloge",""),IF(AND(Profili!AD8=1,Zmožnosti!$D$29=3),"Kavcije/boni/žetoni",""),IF(AND(Profili!AE8=1,Zmožnosti!$D$30=3),"Simulacija",""),IF(AND(Profili!AF8=1,Zmožnosti!$D$31=3),"Samopostrežna ponudba","")) | D8: =_xlfn.TEXTJOIN(", ",TRUE(),IF(AND(Profili!R8=1,Zmožnosti!$D$17=99),"Mize",""),IF(AND(Profili!S8=1,Zmožnosti!$D$18=99),"Kuhinja",""),IF(AND(Profili!T8=1,Zmožnosti!$D$19=99),"Točilnica",""),IF(AND(Profili!U8=1,Zmožnosti!$D$20=99),"Pripravljena hrana",""),IF(AND(Profili!V8=1,Zmožnosti!$D$21=99),"Odpadki",""),IF(AND(Profili!W8=1,Zmožnosti!$D$22=99),"Telefonska naročila",""),IF(AND(Profili!X8=1,Zmožnosti!$D$23=99),"Rezervacije",""),IF(AND(Profili!Y8=1,Zmožnosti!$D$24=99),"Dostava",""),IF(AND(Profili!Z8=1,Zmožnosti!$D$25=99),"QR meni",""),IF(AND(Profili!AA8=1,Zmožnosti!$D$26=99),"Večhodni meniji",""),IF(AND(Profili!AB8=1,Zmožnosti!$D$27=99),"Dogodki",""),IF(AND(Profili!AC8=1,Zmožnosti!$D$28=99),"Prenosi zaloge",""),IF(AND(Profili!AD8=1,Zmožnosti!$D$29=99),"Kavcije/boni/žetoni",""),IF(AND(Profili!AE8=1,Zmožnosti!$D$30=99),"Simulacija",""),IF(AND(Profili!AF8=1,Zmožnosti!$D$31=99),"Samopostrežna ponudba","")) -> Samopostrežna ponudba | E8: =(Profili!R8=1)*(Zmožnosti!$D$17=2)+(Profili!S8=1)*(Zmožnosti!$D$18=2)+(Profili!T8=1)*(Zmožnosti!$D$19=2)+(Profili!U8=1)*(Zmožnosti!$D$20=2)+(Profili!V8=1)*(Zmožnosti!$D$21=2)+(Profili!W8=1)*(Zmožnosti!$D$22=2)+(Profili!X8=1)*(Zmožnosti!$D$23=2)+(Profili!Y8=1)*(Zmožnosti!$D$24=2)+(Profili!Z8=1)*(Zmožnosti!$D$25=2)+(Profili!AA8=1)*(Zmožnosti!$D$26=2)+(Profili!AB8=1)*(Zmožnosti!$D$27=2)+(Profili!AC8=1)*(Zmožnosti!$D$28=2)+(Profili!AD8=1)*(Zmožnosti!$D$29=2)+(Profili!AE8=1)*(Zmožnosti!$D$30=2)+(Profili!AF8=1)*(Zmožnosti!$D$31=2) -> 3 | F8: =(Profili!R8=1)*(Zmožnosti!$D$17=3)+(Profili!S8=1)*(Zmožnosti!$D$18=3)+(Profili!T8=1)*(Zmožnosti!$D$19=3)+(Profili!U8=1)*(Zmožnosti!$D$20=3)+(Profili!V8=1)*(Zmožnosti!$D$21=3)+(Profili!W8=1)*(Zmožnosti!$D$22=3)+(Profili!X8=1)*(Zmožnosti!$D$23=3)+(Profili!Y8=1)*(Zmožnosti!$D$24=3)+(Profili!Z8=1)*(Zmožnosti!$D$25=3)+(Profili!AA8=1)*(Zmožnosti!$D$26=3)+(Profili!AB8=1)*(Zmožnosti!$D$27=3)+(Profili!AC8=1)*(Zmožnosti!$D$28=3)+(Profili!AD8=1)*(Zmožnosti!$D$29=3)+(Profili!AE8=1)*(Zmožnosti!$D$30=3)+(Profili!AF8=1)*(Zmožnosti!$D$31=3) -> 0 | G8: =(Profili!R8=1)*(Zmožnosti!$D$17=99)+(Profili!S8=1)*(Zmožnosti!$D$18=99)+(Profili!T8=1)*(Zmožnosti!$D$19=99)+(Profili!U8=1)*(Zmožnosti!$D$20=99)+(Profili!V8=1)*(Zmožnosti!$D$21=99)+(Profili!W8=1)*(Zmožnosti!$D$22=99)+(Profili!X8=1)*(Zmožnosti!$D$23=99)+(Profili!Y8=1)*(Zmožnosti!$D$24=99)+(Profili!Z8=1)*(Zmožnosti!$D$25=99)+(Profili!AA8=1)*(Zmožnosti!$D$26=99)+(Profili!AB8=1)*(Zmožnosti!$D$27=99)+(Profili!AC8=1)*(Zmožnosti!$D$28=99)+(Profili!AD8=1)*(Zmožnosti!$D$29=99)+(Profili!AE8=1)*(Zmožnosti!$D$30=99)+(Profili!AF8=1)*(Zmožnosti!$D$31=99) -> 1
A9: =Profili!B9 -> Hitra prehrana / kiosk | B9: =_xlfn.TEXTJOIN(", ",TRUE(),IF(AND(Profili!R9=1,Zmožnosti!$D$17=2),"Mize",""),IF(AND(Profili!S9=1,Zmožnosti!$D$18=2),"Kuhinja",""),IF(AND(Profili!T9=1,Zmožnosti!$D$19=2),"Točilnica",""),IF(AND(Profili!U9=1,Zmožnosti!$D$20=2),"Pripravljena hrana",""),IF(AND(Profili!V9=1,Zmožnosti!$D$21=2),"Odpadki",""),IF(AND(Profili!W9=1,Zmožnosti!$D$22=2),"Telefonska naročila",""),IF(AND(Profili!X9=1,Zmožnosti!$D$23=2),"Rezervacije",""),IF(AND(Profili!Y9=1,Zmožnosti!$D$24=2),"Dostava",""),IF(AND(Profili!Z9=1,Zmožnosti!$D$25=2),"QR meni",""),IF(AND(Profili!AA9=1,Zmožnosti!$D$26=2),"Večhodni meniji",""),IF(AND(Profili!AB9=1,Zmožnosti!$D$27=2),"Dogodki",""),IF(AND(Profili!AC9=1,Zmožnosti!$D$28=2),"Prenosi zaloge",""),IF(AND(Profili!AD9=1,Zmožnosti!$D$29=2),"Kavcije/boni/žetoni",""),IF(AND(Profili!AE9=1,Zmožnosti!$D$30=2),"Simulacija",""),IF(AND(Profili!AF9=1,Zmožnosti!$D$31=2),"Samopostrežna ponudba","")) -> Kuhinja, Pripravljena hrana, Telefonska naročila | C9: =_xlfn.TEXTJOIN(", ",TRUE(),IF(AND(Profili!R9=1,Zmožnosti!$D$17=3),"Mize",""),IF(AND(Profili!S9=1,Zmožnosti!$D$18=3),"Kuhinja",""),IF(AND(Profili!T9=1,Zmožnosti!$D$19=3),"Točilnica",""),IF(AND(Profili!U9=1,Zmožnosti!$D$20=3),"Pripravljena hrana",""),IF(AND(Profili!V9=1,Zmožnosti!$D$21=3),"Odpadki",""),IF(AND(Profili!W9=1,Zmožnosti!$D$22=3),"Telefonska naročila",""),IF(AND(Profili!X9=1,Zmožnosti!$D$23=3),"Rezervacije",""),IF(AND(Profili!Y9=1,Zmožnosti!$D$24=3),"Dostava",""),IF(AND(Profili!Z9=1,Zmožnosti!$D$25=3),"QR meni",""),IF(AND(Profili!AA9=1,Zmožnosti!$D$26=3),"Večhodni meniji",""),IF(AND(Profili!AB9=1,Zmožnosti!$D$27=3),"Dogodki",""),IF(AND(Profili!AC9=1,Zmožnosti!$D$28=3),"Prenosi zaloge",""),IF(AND(Profili!AD9=1,Zmožnosti!$D$29=3),"Kavcije/boni/žetoni",""),IF(AND(Profili!AE9=1,Zmožnosti!$D$30=3),"Simulacija",""),IF(AND(Profili!AF9=1,Zmožnosti!$D$31=3),"Samopostrežna ponudba","")) -> Dostava, QR meni | D9: =_xlfn.TEXTJOIN(", ",TRUE(),IF(AND(Profili!R9=1,Zmožnosti!$D$17=99),"Mize",""),IF(AND(Profili!S9=1,Zmožnosti!$D$18=99),"Kuhinja",""),IF(AND(Profili!T9=1,Zmožnosti!$D$19=99),"Točilnica",""),IF(AND(Profili!U9=1,Zmožnosti!$D$20=99),"Pripravljena hrana",""),IF(AND(Profili!V9=1,Zmožnosti!$D$21=99),"Odpadki",""),IF(AND(Profili!W9=1,Zmožnosti!$D$22=99),"Telefonska naročila",""),IF(AND(Profili!X9=1,Zmožnosti!$D$23=99),"Rezervacije",""),IF(AND(Profili!Y9=1,Zmožnosti!$D$24=99),"Dostava",""),IF(AND(Profili!Z9=1,Zmožnosti!$D$25=99),"QR meni",""),IF(AND(Profili!AA9=1,Zmožnosti!$D$26=99),"Večhodni meniji",""),IF(AND(Profili!AB9=1,Zmožnosti!$D$27=99),"Dogodki",""),IF(AND(Profili!AC9=1,Zmožnosti!$D$28=99),"Prenosi zaloge",""),IF(AND(Profili!AD9=1,Zmožnosti!$D$29=99),"Kavcije/boni/žetoni",""),IF(AND(Profili!AE9=1,Zmožnosti!$D$30=99),"Simulacija",""),IF(AND(Profili!AF9=1,Zmožnosti!$D$31=99),"Samopostrežna ponudba","")) | E9: =(Profili!R9=1)*(Zmožnosti!$D$17=2)+(Profili!S9=1)*(Zmožnosti!$D$18=2)+(Profili!T9=1)*(Zmožnosti!$D$19=2)+(Profili!U9=1)*(Zmožnosti!$D$20=2)+(Profili!V9=1)*(Zmožnosti!$D$21=2)+(Profili!W9=1)*(Zmožnosti!$D$22=2)+(Profili!X9=1)*(Zmožnosti!$D$23=2)+(Profili!Y9=1)*(Zmožnosti!$D$24=2)+(Profili!Z9=1)*(Zmožnosti!$D$25=2)+(Profili!AA9=1)*(Zmožnosti!$D$26=2)+(Profili!AB9=1)*(Zmožnosti!$D$27=2)+(Profili!AC9=1)*(Zmožnosti!$D$28=2)+(Profili!AD9=1)*(Zmožnosti!$D$29=2)+(Profili!AE9=1)*(Zmožnosti!$D$30=2)+(Profili!AF9=1)*(Zmožnosti!$D$31=2) -> 3 | F9: =(Profili!R9=1)*(Zmožnosti!$D$17=3)+(Profili!S9=1)*(Zmožnosti!$D$18=3)+(Profili!T9=1)*(Zmožnosti!$D$19=3)+(Profili!U9=1)*(Zmožnosti!$D$20=3)+(Profili!V9=1)*(Zmožnosti!$D$21=3)+(Profili!W9=1)*(Zmožnosti!$D$22=3)+(Profili!X9=1)*(Zmožnosti!$D$23=3)+(Profili!Y9=1)*(Zmožnosti!$D$24=3)+(Profili!Z9=1)*(Zmožnosti!$D$25=3)+(Profili!AA9=1)*(Zmožnosti!$D$26=3)+(Profili!AB9=1)*(Zmožnosti!$D$27=3)+(Profili!AC9=1)*(Zmožnosti!$D$28=3)+(Profili!AD9=1)*(Zmožnosti!$D$29=3)+(Profili!AE9=1)*(Zmožnosti!$D$30=3)+(Profili!AF9=1)*(Zmožnosti!$D$31=3) -> 2 | G9: =(Profili!R9=1)*(Zmožnosti!$D$17=99)+(Profili!S9=1)*(Zmožnosti!$D$18=99)+(Profili!T9=1)*(Zmožnosti!$D$19=99)+(Profili!U9=1)*(Zmožnosti!$D$20=99)+(Profili!V9=1)*(Zmožnosti!$D$21=99)+(Profili!W9=1)*(Zmožnosti!$D$22=99)+(Profili!X9=1)*(Zmožnosti!$D$23=99)+(Profili!Y9=1)*(Zmožnosti!$D$24=99)+(Profili!Z9=1)*(Zmožnosti!$D$25=99)+(Profili!AA9=1)*(Zmožnosti!$D$26=99)+(Profili!AB9=1)*(Zmožnosti!$D$27=99)+(Profili!AC9=1)*(Zmožnosti!$D$28=99)+(Profili!AD9=1)*(Zmožnosti!$D$29=99)+(Profili!AE9=1)*(Zmožnosti!$D$30=99)+(Profili!AF9=1)*(Zmožnosti!$D$31=99) -> 0
A10: =Profili!B10 -> Bar / bife / pub | B10: =_xlfn.TEXTJOIN(", ",TRUE(),IF(AND(Profili!R10=1,Zmožnosti!$D$17=2),"Mize",""),IF(AND(Profili!S10=1,Zmožnosti!$D$18=2),"Kuhinja",""),IF(AND(Profili!T10=1,Zmožnosti!$D$19=2),"Točilnica",""),IF(AND(Profili!U10=1,Zmožnosti!$D$20=2),"Pripravljena hrana",""),IF(AND(Profili!V10=1,Zmožnosti!$D$21=2),"Odpadki",""),IF(AND(Profili!W10=1,Zmožnosti!$D$22=2),"Telefonska naročila",""),IF(AND(Profili!X10=1,Zmožnosti!$D$23=2),"Rezervacije",""),IF(AND(Profili!Y10=1,Zmožnosti!$D$24=2),"Dostava",""),IF(AND(Profili!Z10=1,Zmožnosti!$D$25=2),"QR meni",""),IF(AND(Profili!AA10=1,Zmožnosti!$D$26=2),"Večhodni meniji",""),IF(AND(Profili!AB10=1,Zmožnosti!$D$27=2),"Dogodki",""),IF(AND(Profili!AC10=1,Zmožnosti!$D$28=2),"Prenosi zaloge",""),IF(AND(Profili!AD10=1,Zmožnosti!$D$29=2),"Kavcije/boni/žetoni",""),IF(AND(Profili!AE10=1,Zmožnosti!$D$30=2),"Simulacija",""),IF(AND(Profili!AF10=1,Zmožnosti!$D$31=2),"Samopostrežna ponudba","")) -> Mize, Točilnica | C10: =_xlfn.TEXTJOIN(", ",TRUE(),IF(AND(Profili!R10=1,Zmožnosti!$D$17=3),"Mize",""),IF(AND(Profili!S10=1,Zmožnosti!$D$18=3),"Kuhinja",""),IF(AND(Profili!T10=1,Zmožnosti!$D$19=3),"Točilnica",""),IF(AND(Profili!U10=1,Zmožnosti!$D$20=3),"Pripravljena hrana",""),IF(AND(Profili!V10=1,Zmožnosti!$D$21=3),"Odpadki",""),IF(AND(Profili!W10=1,Zmožnosti!$D$22=3),"Telefonska naročila",""),IF(AND(Profili!X10=1,Zmožnosti!$D$23=3),"Rezervacije",""),IF(AND(Profili!Y10=1,Zmožnosti!$D$24=3),"Dostava",""),IF(AND(Profili!Z10=1,Zmožnosti!$D$25=3),"QR meni",""),IF(AND(Profili!AA10=1,Zmožnosti!$D$26=3),"Večhodni meniji",""),IF(AND(Profili!AB10=1,Zmožnosti!$D$27=3),"Dogodki",""),IF(AND(Profili!AC10=1,Zmožnosti!$D$28=3),"Prenosi zaloge",""),IF(AND(Profili!AD10=1,Zmožnosti!$D$29=3),"Kavcije/boni/žetoni",""),IF(AND(Profili!AE10=1,Zmožnosti!$D$30=3),"Simulacija",""),IF(AND(Profili!AF10=1,Zmožnosti!$D$31=3),"Samopostrežna ponudba","")) -> QR meni | D10: =_xlfn.TEXTJOIN(", ",TRUE(),IF(AND(Profili!R10=1,Zmožnosti!$D$17=99),"Mize",""),IF(AND(Profili!S10=1,Zmožnosti!$D$18=99),"Kuhinja",""),IF(AND(Profili!T10=1,Zmožnosti!$D$19=99),"Točilnica",""),IF(AND(Profili!U10=1,Zmožnosti!$D$20=99),"Pripravljena hrana",""),IF(AND(Profili!V10=1,Zmožnosti!$D$21=99),"Odpadki",""),IF(AND(Profili!W10=1,Zmožnosti!$D$22=99),"Telefonska naročila",""),IF(AND(Profili!X10=1,Zmožnosti!$D$23=99),"Rezervacije",""),IF(AND(Profili!Y10=1,Zmožnosti!$D$24=99),"Dostava",""),IF(AND(Profili!Z10=1,Zmožnosti!$D$25=99),"QR meni",""),IF(AND(Profili!AA10=1,Zmožnosti!$D$26=99),"Večhodni meniji",""),IF(AND(Profili!AB10=1,Zmožnosti!$D$27=99),"Dogodki",""),IF(AND(Profili!AC10=1,Zmožnosti!$D$28=99),"Prenosi zaloge",""),IF(AND(Profili!AD10=1,Zmožnosti!$D$29=99),"Kavcije/boni/žetoni",""),IF(AND(Profili!AE10=1,Zmožnosti!$D$30=99),"Simulacija",""),IF(AND(Profili!AF10=1,Zmožnosti!$D$31=99),"Samopostrežna ponudba","")) | E10: =(Profili!R10=1)*(Zmožnosti!$D$17=2)+(Profili!S10=1)*(Zmožnosti!$D$18=2)+(Profili!T10=1)*(Zmožnosti!$D$19=2)+(Profili!U10=1)*(Zmožnosti!$D$20=2)+(Profili!V10=1)*(Zmožnosti!$D$21=2)+(Profili!W10=1)*(Zmožnosti!$D$22=2)+(Profili!X10=1)*(Zmožnosti!$D$23=2)+(Profili!Y10=1)*(Zmožnosti!$D$24=2)+(Profili!Z10=1)*(Zmožnosti!$D$25=2)+(Profili!AA10=1)*(Zmožnosti!$D$26=2)+(Profili!AB10=1)*(Zmožnosti!$D$27=2)+(Profili!AC10=1)*(Zmožnosti!$D$28=2)+(Profili!AD10=1)*(Zmožnosti!$D$29=2)+(Profili!AE10=1)*(Zmožnosti!$D$30=2)+(Profili!AF10=1)*(Zmožnosti!$D$31=2) -> 2 | F10: =(Profili!R10=1)*(Zmožnosti!$D$17=3)+(Profili!S10=1)*(Zmožnosti!$D$18=3)+(Profili!T10=1)*(Zmožnosti!$D$19=3)+(Profili!U10=1)*(Zmožnosti!$D$20=3)+(Profili!V10=1)*(Zmožnosti!$D$21=3)+(Profili!W10=1)*(Zmožnosti!$D$22=3)+(Profili!X10=1)*(Zmožnosti!$D$23=3)+(Profili!Y10=1)*(Zmožnosti!$D$24=3)+(Profili!Z10=1)*(Zmožnosti!$D$25=3)+(Profili!AA10=1)*(Zmožnosti!$D$26=3)+(Profili!AB10=1)*(Zmožnosti!$D$27=3)+(Profili!AC10=1)*(Zmožnosti!$D$28=3)+(Profili!AD10=1)*(Zmožnosti!$D$29=3)+(Profili!AE10=1)*(Zmožnosti!$D$30=3)+(Profili!AF10=1)*(Zmožnosti!$D$31=3) -> 1 | G10: =(Profili!R10=1)*(Zmožnosti!$D$17=99)+(Profili!S10=1)*(Zmožnosti!$D$18=99)+(Profili!T10=1)*(Zmožnosti!$D$19=99)+(Profili!U10=1)*(Zmožnosti!$D$20=99)+(Profili!V10=1)*(Zmožnosti!$D$21=99)+(Profili!W10=1)*(Zmožnosti!$D$22=99)+(Profili!X10=1)*(Zmožnosti!$D$23=99)+(Profili!Y10=1)*(Zmožnosti!$D$24=99)+(Profili!Z10=1)*(Zmožnosti!$D$25=99)+(Profili!AA10=1)*(Zmožnosti!$D$26=99)+(Profili!AB10=1)*(Zmožnosti!$D$27=99)+(Profili!AC10=1)*(Zmožnosti!$D$28=99)+(Profili!AD10=1)*(Zmožnosti!$D$29=99)+(Profili!AE10=1)*(Zmožnosti!$D$30=99)+(Profili!AF10=1)*(Zmožnosti!$D$31=99) -> 0
A11: =Profili!B11 -> Kavarna / slaščičarna | B11: =_xlfn.TEXTJOIN(", ",TRUE(),IF(AND(Profili!R11=1,Zmožnosti!$D$17=2),"Mize",""),IF(AND(Profili!S11=1,Zmožnosti!$D$18=2),"Kuhinja",""),IF(AND(Profili!T11=1,Zmožnosti!$D$19=2),"Točilnica",""),IF(AND(Profili!U11=1,Zmožnosti!$D$20=2),"Pripravljena hrana",""),IF(AND(Profili!V11=1,Zmožnosti!$D$21=2),"Odpadki",""),IF(AND(Profili!W11=1,Zmožnosti!$D$22=2),"Telefonska naročila",""),IF(AND(Profili!X11=1,Zmožnosti!$D$23=2),"Rezervacije",""),IF(AND(Profili!Y11=1,Zmožnosti!$D$24=2),"Dostava",""),IF(AND(Profili!Z11=1,Zmožnosti!$D$25=2),"QR meni",""),IF(AND(Profili!AA11=1,Zmožnosti!$D$26=2),"Večhodni meniji",""),IF(AND(Profili!AB11=1,Zmožnosti!$D$27=2),"Dogodki",""),IF(AND(Profili!AC11=1,Zmožnosti!$D$28=2),"Prenosi zaloge",""),IF(AND(Profili!AD11=1,Zmožnosti!$D$29=2),"Kavcije/boni/žetoni",""),IF(AND(Profili!AE11=1,Zmožnosti!$D$30=2),"Simulacija",""),IF(AND(Profili!AF11=1,Zmožnosti!$D$31=2),"Samopostrežna ponudba","")) -> Mize, Točilnica, Pripravljena hrana, Telefonska naročila | C11: =_xlfn.TEXTJOIN(", ",TRUE(),IF(AND(Profili!R11=1,Zmožnosti!$D$17=3),"Mize",""),IF(AND(Profili!S11=1,Zmožnosti!$D$18=3),"Kuhinja",""),IF(AND(Profili!T11=1,Zmožnosti!$D$19=3),"Točilnica",""),IF(AND(Profili!U11=1,Zmožnosti!$D$20=3),"Pripravljena hrana",""),IF(AND(Profili!V11=1,Zmožnosti!$D$21=3),"Odpadki",""),IF(AND(Profili!W11=1,Zmožnosti!$D$22=3),"Telefonska naročila",""),IF(AND(Profili!X11=1,Zmožnosti!$D$23=3),"Rezervacije",""),IF(AND(Profili!Y11=1,Zmožnosti!$D$24=3),"Dostava",""),IF(AND(Profili!Z11=1,Zmožnosti!$D$25=3),"QR meni",""),IF(AND(Profili!AA11=1,Zmožnosti!$D$26=3),"Večhodni meniji",""),IF(AND(Profili!AB11=1,Zmožnosti!$D$27=3),"Dogodki",""),IF(AND(Profili!AC11=1,Zmožnosti!$D$28=3),"Prenosi zaloge",""),IF(AND(Profili!AD11=1,Zmožnosti!$D$29=3),"Kavcije/boni/žetoni",""),IF(AND(Profili!AE11=1,Zmožnosti!$D$30=3),"Simulacija",""),IF(AND(Profili!AF11=1,Zmožnosti!$D$31=3),"Samopostrežna ponudba","")) -> QR meni | D11: =_xlfn.TEXTJOIN(", ",TRUE(),IF(AND(Profili!R11=1,Zmožnosti!$D$17=99),"Mize",""),IF(AND(Profili!S11=1,Zmožnosti!$D$18=99),"Kuhinja",""),IF(AND(Profili!T11=1,Zmožnosti!$D$19=99),"Točilnica",""),IF(AND(Profili!U11=1,Zmožnosti!$D$20=99),"Pripravljena hrana",""),IF(AND(Profili!V11=1,Zmožnosti!$D$21=99),"Odpadki",""),IF(AND(Profili!W11=1,Zmožnosti!$D$22=99),"Telefonska naročila",""),IF(AND(Profili!X11=1,Zmožnosti!$D$23=99),"Rezervacije",""),IF(AND(Profili!Y11=1,Zmožnosti!$D$24=99),"Dostava",""),IF(AND(Profili!Z11=1,Zmožnosti!$D$25=99),"QR meni",""),IF(AND(Profili!AA11=1,Zmožnosti!$D$26=99),"Večhodni meniji",""),IF(AND(Profili!AB11=1,Zmožnosti!$D$27=99),"Dogodki",""),IF(AND(Profili!AC11=1,Zmožnosti!$D$28=99),"Prenosi zaloge",""),IF(AND(Profili!AD11=1,Zmožnosti!$D$29=99),"Kavcije/boni/žetoni",""),IF(AND(Profili!AE11=1,Zmožnosti!$D$30=99),"Simulacija",""),IF(AND(Profili!AF11=1,Zmožnosti!$D$31=99),"Samopostrežna ponudba","")) | E11: =(Profili!R11=1)*(Zmožnosti!$D$17=2)+(Profili!S11=1)*(Zmožnosti!$D$18=2)+(Profili!T11=1)*(Zmožnosti!$D$19=2)+(Profili!U11=1)*(Zmožnosti!$D$20=2)+(Profili!V11=1)*(Zmožnosti!$D$21=2)+(Profili!W11=1)*(Zmožnosti!$D$22=2)+(Profili!X11=1)*(Zmožnosti!$D$23=2)+(Profili!Y11=1)*(Zmožnosti!$D$24=2)+(Profili!Z11=1)*(Zmožnosti!$D$25=2)+(Profili!AA11=1)*(Zmožnosti!$D$26=2)+(Profili!AB11=1)*(Zmožnosti!$D$27=2)+(Profili!AC11=1)*(Zmožnosti!$D$28=2)+(Profili!AD11=1)*(Zmožnosti!$D$29=2)+(Profili!AE11=1)*(Zmožnosti!$D$30=2)+(Profili!AF11=1)*(Zmožnosti!$D$31=2) -> 4 | F11: =(Profili!R11=1)*(Zmožnosti!$D$17=3)+(Profili!S11=1)*(Zmožnosti!$D$18=3)+(Profili!T11=1)*(Zmožnosti!$D$19=3)+(Profili!U11=1)*(Zmožnosti!$D$20=3)+(Profili!V11=1)*(Zmožnosti!$D$21=3)+(Profili!W11=1)*(Zmožnosti!$D$22=3)+(Profili!X11=1)*(Zmožnosti!$D$23=3)+(Profili!Y11=1)*(Zmožnosti!$D$24=3)+(Profili!Z11=1)*(Zmožnosti!$D$25=3)+(Profili!AA11=1)*(Zmožnosti!$D$26=3)+(Profili!AB11=1)*(Zmožnosti!$D$27=3)+(Profili!AC11=1)*(Zmožnosti!$D$28=3)+(Profili!AD11=1)*(Zmožnosti!$D$29=3)+(Profili!AE11=1)*(Zmožnosti!$D$30=3)+(Profili!AF11=1)*(Zmožnosti!$D$31=3) -> 1 | G11: =(Profili!R11=1)*(Zmožnosti!$D$17=99)+(Profili!S11=1)*(Zmožnosti!$D$18=99)+(Profili!T11=1)*(Zmožnosti!$D$19=99)+(Profili!U11=1)*(Zmožnosti!$D$20=99)+(Profili!V11=1)*(Zmožnosti!$D$21=99)+(Profili!W11=1)*(Zmožnosti!$D$22=99)+(Profili!X11=1)*(Zmožnosti!$D$23=99)+(Profili!Y11=1)*(Zmožnosti!$D$24=99)+(Profili!Z11=1)*(Zmožnosti!$D$25=99)+(Profili!AA11=1)*(Zmožnosti!$D$26=99)+(Profili!AB11=1)*(Zmožnosti!$D$27=99)+(Profili!AC11=1)*(Zmožnosti!$D$28=99)+(Profili!AD11=1)*(Zmožnosti!$D$29=99)+(Profili!AE11=1)*(Zmožnosti!$D$30=99)+(Profili!AF11=1)*(Zmožnosti!$D$31=99) -> 0
A12: =Profili!B12 -> Turistična kmetija / osmica | B12: =_xlfn.TEXTJOIN(", ",TRUE(),IF(AND(Profili!R12=1,Zmožnosti!$D$17=2),"Mize",""),IF(AND(Profili!S12=1,Zmožnosti!$D$18=2),"Kuhinja",""),IF(AND(Profili!T12=1,Zmožnosti!$D$19=2),"Točilnica",""),IF(AND(Profili!U12=1,Zmožnosti!$D$20=2),"Pripravljena hrana",""),IF(AND(Profili!V12=1,Zmožnosti!$D$21=2),"Odpadki",""),IF(AND(Profili!W12=1,Zmožnosti!$D$22=2),"Telefonska naročila",""),IF(AND(Profili!X12=1,Zmožnosti!$D$23=2),"Rezervacije",""),IF(AND(Profili!Y12=1,Zmožnosti!$D$24=2),"Dostava",""),IF(AND(Profili!Z12=1,Zmožnosti!$D$25=2),"QR meni",""),IF(AND(Profili!AA12=1,Zmožnosti!$D$26=2),"Večhodni meniji",""),IF(AND(Profili!AB12=1,Zmožnosti!$D$27=2),"Dogodki",""),IF(AND(Profili!AC12=1,Zmožnosti!$D$28=2),"Prenosi zaloge",""),IF(AND(Profili!AD12=1,Zmožnosti!$D$29=2),"Kavcije/boni/žetoni",""),IF(AND(Profili!AE12=1,Zmožnosti!$D$30=2),"Simulacija",""),IF(AND(Profili!AF12=1,Zmožnosti!$D$31=2),"Samopostrežna ponudba","")) -> Mize, Kuhinja, Točilnica, Pripravljena hrana | C12: =_xlfn.TEXTJOIN(", ",TRUE(),IF(AND(Profili!R12=1,Zmožnosti!$D$17=3),"Mize",""),IF(AND(Profili!S12=1,Zmožnosti!$D$18=3),"Kuhinja",""),IF(AND(Profili!T12=1,Zmožnosti!$D$19=3),"Točilnica",""),IF(AND(Profili!U12=1,Zmožnosti!$D$20=3),"Pripravljena hrana",""),IF(AND(Profili!V12=1,Zmožnosti!$D$21=3),"Odpadki",""),IF(AND(Profili!W12=1,Zmožnosti!$D$22=3),"Telefonska naročila",""),IF(AND(Profili!X12=1,Zmožnosti!$D$23=3),"Rezervacije",""),IF(AND(Profili!Y12=1,Zmožnosti!$D$24=3),"Dostava",""),IF(AND(Profili!Z12=1,Zmožnosti!$D$25=3),"QR meni",""),IF(AND(Profili!AA12=1,Zmožnosti!$D$26=3),"Večhodni meniji",""),IF(AND(Profili!AB12=1,Zmožnosti!$D$27=3),"Dogodki",""),IF(AND(Profili!AC12=1,Zmožnosti!$D$28=3),"Prenosi zaloge",""),IF(AND(Profili!AD12=1,Zmožnosti!$D$29=3),"Kavcije/boni/žetoni",""),IF(AND(Profili!AE12=1,Zmožnosti!$D$30=3),"Simulacija",""),IF(AND(Profili!AF12=1,Zmožnosti!$D$31=3),"Samopostrežna ponudba","")) -> Rezervacije, Dogodki | D12: =_xlfn.TEXTJOIN(", ",TRUE(),IF(AND(Profili!R12=1,Zmožnosti!$D$17=99),"Mize",""),IF(AND(Profili!S12=1,Zmožnosti!$D$18=99),"Kuhinja",""),IF(AND(Profili!T12=1,Zmožnosti!$D$19=99),"Točilnica",""),IF(AND(Profili!U12=1,Zmožnosti!$D$20=99),"Pripravljena hrana",""),IF(AND(Profili!V12=1,Zmožnosti!$D$21=99),"Odpadki",""),IF(AND(Profili!W12=1,Zmožnosti!$D$22=99),"Telefonska naročila",""),IF(AND(Profili!X12=1,Zmožnosti!$D$23=99),"Rezervacije",""),IF(AND(Profili!Y12=1,Zmožnosti!$D$24=99),"Dostava",""),IF(AND(Profili!Z12=1,Zmožnosti!$D$25=99),"QR meni",""),IF(AND(Profili!AA12=1,Zmožnosti!$D$26=99),"Večhodni meniji",""),IF(AND(Profili!AB12=1,Zmožnosti!$D$27=99),"Dogodki",""),IF(AND(Profili!AC12=1,Zmožnosti!$D$28=99),"Prenosi zaloge",""),IF(AND(Profili!AD12=1,Zmožnosti!$D$29=99),"Kavcije/boni/žetoni",""),IF(AND(Profili!AE12=1,Zmožnosti!$D$30=99),"Simulacija",""),IF(AND(Profili!AF12=1,Zmožnosti!$D$31=99),"Samopostrežna ponudba","")) | E12: =(Profili!R12=1)*(Zmožnosti!$D$17=2)+(Profili!S12=1)*(Zmožnosti!$D$18=2)+(Profili!T12=1)*(Zmožnosti!$D$19=2)+(Profili!U12=1)*(Zmožnosti!$D$20=2)+(Profili!V12=1)*(Zmožnosti!$D$21=2)+(Profili!W12=1)*(Zmožnosti!$D$22=2)+(Profili!X12=1)*(Zmožnosti!$D$23=2)+(Profili!Y12=1)*(Zmožnosti!$D$24=2)+(Profili!Z12=1)*(Zmožnosti!$D$25=2)+(Profili!AA12=1)*(Zmožnosti!$D$26=2)+(Profili!AB12=1)*(Zmožnosti!$D$27=2)+(Profili!AC12=1)*(Zmožnosti!$D$28=2)+(Profili!AD12=1)*(Zmožnosti!$D$29=2)+(Profili!AE12=1)*(Zmožnosti!$D$30=2)+(Profili!AF12=1)*(Zmožnosti!$D$31=2) -> 4 | F12: =(Profili!R12=1)*(Zmožnosti!$D$17=3)+(Profili!S12=1)*(Zmožnosti!$D$18=3)+(Profili!T12=1)*(Zmožnosti!$D$19=3)+(Profili!U12=1)*(Zmožnosti!$D$20=3)+(Profili!V12=1)*(Zmožnosti!$D$21=3)+(Profili!W12=1)*(Zmožnosti!$D$22=3)+(Profili!X12=1)*(Zmožnosti!$D$23=3)+(Profili!Y12=1)*(Zmožnosti!$D$24=3)+(Profili!Z12=1)*(Zmožnosti!$D$25=3)+(Profili!AA12=1)*(Zmožnosti!$D$26=3)+(Profili!AB12=1)*(Zmožnosti!$D$27=3)+(Profili!AC12=1)*(Zmožnosti!$D$28=3)+(Profili!AD12=1)*(Zmožnosti!$D$29=3)+(Profili!AE12=1)*(Zmožnosti!$D$30=3)+(Profili!AF12=1)*(Zmožnosti!$D$31=3) -> 2 | G12: =(Profili!R12=1)*(Zmožnosti!$D$17=99)+(Profili!S12=1)*(Zmožnosti!$D$18=99)+(Profili!T12=1)*(Zmožnosti!$D$19=99)+(Profili!U12=1)*(Zmožnosti!$D$20=99)+(Profili!V12=1)*(Zmožnosti!$D$21=99)+(Profili!W12=1)*(Zmožnosti!$D$22=99)+(Profili!X12=1)*(Zmožnosti!$D$23=99)+(Profili!Y12=1)*(Zmožnosti!$D$24=99)+(Profili!Z12=1)*(Zmožnosti!$D$25=99)+(Profili!AA12=1)*(Zmožnosti!$D$26=99)+(Profili!AB12=1)*(Zmožnosti!$D$27=99)+(Profili!AC12=1)*(Zmožnosti!$D$28=99)+(Profili!AD12=1)*(Zmožnosti!$D$29=99)+(Profili!AE12=1)*(Zmožnosti!$D$30=99)+(Profili!AF12=1)*(Zmožnosti!$D$31=99) -> 0
A13: =Profili!B13 -> Društvo / veselica | B13: =_xlfn.TEXTJOIN(", ",TRUE(),IF(AND(Profili!R13=1,Zmožnosti!$D$17=2),"Mize",""),IF(AND(Profili!S13=1,Zmožnosti!$D$18=2),"Kuhinja",""),IF(AND(Profili!T13=1,Zmožnosti!$D$19=2),"Točilnica",""),IF(AND(Profili!U13=1,Zmožnosti!$D$20=2),"Pripravljena hrana",""),IF(AND(Profili!V13=1,Zmožnosti!$D$21=2),"Odpadki",""),IF(AND(Profili!W13=1,Zmožnosti!$D$22=2),"Telefonska naročila",""),IF(AND(Profili!X13=1,Zmožnosti!$D$23=2),"Rezervacije",""),IF(AND(Profili!Y13=1,Zmožnosti!$D$24=2),"Dostava",""),IF(AND(Profili!Z13=1,Zmožnosti!$D$25=2),"QR meni",""),IF(AND(Profili!AA13=1,Zmožnosti!$D$26=2),"Večhodni meniji",""),IF(AND(Profili!AB13=1,Zmožnosti!$D$27=2),"Dogodki",""),IF(AND(Profili!AC13=1,Zmožnosti!$D$28=2),"Prenosi zaloge",""),IF(AND(Profili!AD13=1,Zmožnosti!$D$29=2),"Kavcije/boni/žetoni",""),IF(AND(Profili!AE13=1,Zmožnosti!$D$30=2),"Simulacija",""),IF(AND(Profili!AF13=1,Zmožnosti!$D$31=2),"Samopostrežna ponudba","")) -> Kuhinja, Točilnica | C13: =_xlfn.TEXTJOIN(", ",TRUE(),IF(AND(Profili!R13=1,Zmožnosti!$D$17=3),"Mize",""),IF(AND(Profili!S13=1,Zmožnosti!$D$18=3),"Kuhinja",""),IF(AND(Profili!T13=1,Zmožnosti!$D$19=3),"Točilnica",""),IF(AND(Profili!U13=1,Zmožnosti!$D$20=3),"Pripravljena hrana",""),IF(AND(Profili!V13=1,Zmožnosti!$D$21=3),"Odpadki",""),IF(AND(Profili!W13=1,Zmožnosti!$D$22=3),"Telefonska naročila",""),IF(AND(Profili!X13=1,Zmožnosti!$D$23=3),"Rezervacije",""),IF(AND(Profili!Y13=1,Zmožnosti!$D$24=3),"Dostava",""),IF(AND(Profili!Z13=1,Zmožnosti!$D$25=3),"QR meni",""),IF(AND(Profili!AA13=1,Zmožnosti!$D$26=3),"Večhodni meniji",""),IF(AND(Profili!AB13=1,Zmožnosti!$D$27=3),"Dogodki",""),IF(AND(Profili!AC13=1,Zmožnosti!$D$28=3),"Prenosi zaloge",""),IF(AND(Profili!AD13=1,Zmožnosti!$D$29=3),"Kavcije/boni/žetoni",""),IF(AND(Profili!AE13=1,Zmožnosti!$D$30=3),"Simulacija",""),IF(AND(Profili!AF13=1,Zmožnosti!$D$31=3),"Samopostrežna ponudba","")) -> Dogodki, Prenosi zaloge, Kavcije/boni/žetoni | D13: =_xlfn.TEXTJOIN(", ",TRUE(),IF(AND(Profili!R13=1,Zmožnosti!$D$17=99),"Mize",""),IF(AND(Profili!S13=1,Zmožnosti!$D$18=99),"Kuhinja",""),IF(AND(Profili!T13=1,Zmožnosti!$D$19=99),"Točilnica",""),IF(AND(Profili!U13=1,Zmožnosti!$D$20=99),"Pripravljena hrana",""),IF(AND(Profili!V13=1,Zmožnosti!$D$21=99),"Odpadki",""),IF(AND(Profili!W13=1,Zmožnosti!$D$22=99),"Telefonska naročila",""),IF(AND(Profili!X13=1,Zmožnosti!$D$23=99),"Rezervacije",""),IF(AND(Profili!Y13=1,Zmožnosti!$D$24=99),"Dostava",""),IF(AND(Profili!Z13=1,Zmožnosti!$D$25=99),"QR meni",""),IF(AND(Profili!AA13=1,Zmožnosti!$D$26=99),"Večhodni meniji",""),IF(AND(Profili!AB13=1,Zmožnosti!$D$27=99),"Dogodki",""),IF(AND(Profili!AC13=1,Zmožnosti!$D$28=99),"Prenosi zaloge",""),IF(AND(Profili!AD13=1,Zmožnosti!$D$29=99),"Kavcije/boni/žetoni",""),IF(AND(Profili!AE13=1,Zmožnosti!$D$30=99),"Simulacija",""),IF(AND(Profili!AF13=1,Zmožnosti!$D$31=99),"Samopostrežna ponudba","")) | E13: =(Profili!R13=1)*(Zmožnosti!$D$17=2)+(Profili!S13=1)*(Zmožnosti!$D$18=2)+(Profili!T13=1)*(Zmožnosti!$D$19=2)+(Profili!U13=1)*(Zmožnosti!$D$20=2)+(Profili!V13=1)*(Zmožnosti!$D$21=2)+(Profili!W13=1)*(Zmožnosti!$D$22=2)+(Profili!X13=1)*(Zmožnosti!$D$23=2)+(Profili!Y13=1)*(Zmožnosti!$D$24=2)+(Profili!Z13=1)*(Zmožnosti!$D$25=2)+(Profili!AA13=1)*(Zmožnosti!$D$26=2)+(Profili!AB13=1)*(Zmožnosti!$D$27=2)+(Profili!AC13=1)*(Zmožnosti!$D$28=2)+(Profili!AD13=1)*(Zmožnosti!$D$29=2)+(Profili!AE13=1)*(Zmožnosti!$D$30=2)+(Profili!AF13=1)*(Zmožnosti!$D$31=2) -> 2 | F13: =(Profili!R13=1)*(Zmožnosti!$D$17=3)+(Profili!S13=1)*(Zmožnosti!$D$18=3)+(Profili!T13=1)*(Zmožnosti!$D$19=3)+(Profili!U13=1)*(Zmožnosti!$D$20=3)+(Profili!V13=1)*(Zmožnosti!$D$21=3)+(Profili!W13=1)*(Zmožnosti!$D$22=3)+(Profili!X13=1)*(Zmožnosti!$D$23=3)+(Profili!Y13=1)*(Zmožnosti!$D$24=3)+(Profili!Z13=1)*(Zmožnosti!$D$25=3)+(Profili!AA13=1)*(Zmožnosti!$D$26=3)+(Profili!AB13=1)*(Zmožnosti!$D$27=3)+(Profili!AC13=1)*(Zmožnosti!$D$28=3)+(Profili!AD13=1)*(Zmožnosti!$D$29=3)+(Profili!AE13=1)*(Zmožnosti!$D$30=3)+(Profili!AF13=1)*(Zmožnosti!$D$31=3) -> 3 | G13: =(Profili!R13=1)*(Zmožnosti!$D$17=99)+(Profili!S13=1)*(Zmožnosti!$D$18=99)+(Profili!T13=1)*(Zmožnosti!$D$19=99)+(Profili!U13=1)*(Zmožnosti!$D$20=99)+(Profili!V13=1)*(Zmožnosti!$D$21=99)+(Profili!W13=1)*(Zmožnosti!$D$22=99)+(Profili!X13=1)*(Zmožnosti!$D$23=99)+(Profili!Y13=1)*(Zmožnosti!$D$24=99)+(Profili!Z13=1)*(Zmožnosti!$D$25=99)+(Profili!AA13=1)*(Zmožnosti!$D$26=99)+(Profili!AB13=1)*(Zmožnosti!$D$27=99)+(Profili!AC13=1)*(Zmožnosti!$D$28=99)+(Profili!AD13=1)*(Zmožnosti!$D$29=99)+(Profili!AE13=1)*(Zmožnosti!$D$30=99)+(Profili!AF13=1)*(Zmožnosti!$D$31=99) -> 0
A14: =Profili!B14 -> Prireditvena stojnica | B14: =_xlfn.TEXTJOIN(", ",TRUE(),IF(AND(Profili!R14=1,Zmožnosti!$D$17=2),"Mize",""),IF(AND(Profili!S14=1,Zmožnosti!$D$18=2),"Kuhinja",""),IF(AND(Profili!T14=1,Zmožnosti!$D$19=2),"Točilnica",""),IF(AND(Profili!U14=1,Zmožnosti!$D$20=2),"Pripravljena hrana",""),IF(AND(Profili!V14=1,Zmožnosti!$D$21=2),"Odpadki",""),IF(AND(Profili!W14=1,Zmožnosti!$D$22=2),"Telefonska naročila",""),IF(AND(Profili!X14=1,Zmožnosti!$D$23=2),"Rezervacije",""),IF(AND(Profili!Y14=1,Zmožnosti!$D$24=2),"Dostava",""),IF(AND(Profili!Z14=1,Zmožnosti!$D$25=2),"QR meni",""),IF(AND(Profili!AA14=1,Zmožnosti!$D$26=2),"Večhodni meniji",""),IF(AND(Profili!AB14=1,Zmožnosti!$D$27=2),"Dogodki",""),IF(AND(Profili!AC14=1,Zmožnosti!$D$28=2),"Prenosi zaloge",""),IF(AND(Profili!AD14=1,Zmožnosti!$D$29=2),"Kavcije/boni/žetoni",""),IF(AND(Profili!AE14=1,Zmožnosti!$D$30=2),"Simulacija",""),IF(AND(Profili!AF14=1,Zmožnosti!$D$31=2),"Samopostrežna ponudba","")) -> Kuhinja, Točilnica | C14: =_xlfn.TEXTJOIN(", ",TRUE(),IF(AND(Profili!R14=1,Zmožnosti!$D$17=3),"Mize",""),IF(AND(Profili!S14=1,Zmožnosti!$D$18=3),"Kuhinja",""),IF(AND(Profili!T14=1,Zmožnosti!$D$19=3),"Točilnica",""),IF(AND(Profili!U14=1,Zmožnosti!$D$20=3),"Pripravljena hrana",""),IF(AND(Profili!V14=1,Zmožnosti!$D$21=3),"Odpadki",""),IF(AND(Profili!W14=1,Zmožnosti!$D$22=3),"Telefonska naročila",""),IF(AND(Profili!X14=1,Zmožnosti!$D$23=3),"Rezervacije",""),IF(AND(Profili!Y14=1,Zmožnosti!$D$24=3),"Dostava",""),IF(AND(Profili!Z14=1,Zmožnosti!$D$25=3),"QR meni",""),IF(AND(Profili!AA14=1,Zmožnosti!$D$26=3),"Večhodni meniji",""),IF(AND(Profili!AB14=1,Zmožnosti!$D$27=3),"Dogodki",""),IF(AND(Profili!AC14=1,Zmožnosti!$D$28=3),"Prenosi zaloge",""),IF(AND(Profili!AD14=1,Zmožnosti!$D$29=3),"Kavcije/boni/žetoni",""),IF(AND(Profili!AE14=1,Zmožnosti!$D$30=3),"Simulacija",""),IF(AND(Profili!AF14=1,Zmožnosti!$D$31=3),"Samopostrežna ponudba","")) -> Dogodki, Prenosi zaloge, Kavcije/boni/žetoni | D14: =_xlfn.TEXTJOIN(", ",TRUE(),IF(AND(Profili!R14=1,Zmožnosti!$D$17=99),"Mize",""),IF(AND(Profili!S14=1,Zmožnosti!$D$18=99),"Kuhinja",""),IF(AND(Profili!T14=1,Zmožnosti!$D$19=99),"Točilnica",""),IF(AND(Profili!U14=1,Zmožnosti!$D$20=99),"Pripravljena hrana",""),IF(AND(Profili!V14=1,Zmožnosti!$D$21=99),"Odpadki",""),IF(AND(Profili!W14=1,Zmožnosti!$D$22=99),"Telefonska naročila",""),IF(AND(Profili!X14=1,Zmožnosti!$D$23=99),"Rezervacije",""),IF(AND(Profili!Y14=1,Zmožnosti!$D$24=99),"Dostava",""),IF(AND(Profili!Z14=1,Zmožnosti!$D$25=99),"QR meni",""),IF(AND(Profili!AA14=1,Zmožnosti!$D$26=99),"Večhodni meniji",""),IF(AND(Profili!AB14=1,Zmožnosti!$D$27=99),"Dogodki",""),IF(AND(Profili!AC14=1,Zmožnosti!$D$28=99),"Prenosi zaloge",""),IF(AND(Profili!AD14=1,Zmožnosti!$D$29=99),"Kavcije/boni/žetoni",""),IF(AND(Profili!AE14=1,Zmožnosti!$D$30=99),"Simulacija",""),IF(AND(Profili!AF14=1,Zmožnosti!$D$31=99),"Samopostrežna ponudba","")) | E14: =(Profili!R14=1)*(Zmožnosti!$D$17=2)+(Profili!S14=1)*(Zmožnosti!$D$18=2)+(Profili!T14=1)*(Zmožnosti!$D$19=2)+(Profili!U14=1)*(Zmožnosti!$D$20=2)+(Profili!V14=1)*(Zmožnosti!$D$21=2)+(Profili!W14=1)*(Zmožnosti!$D$22=2)+(Profili!X14=1)*(Zmožnosti!$D$23=2)+(Profili!Y14=1)*(Zmožnosti!$D$24=2)+(Profili!Z14=1)*(Zmožnosti!$D$25=2)+(Profili!AA14=1)*(Zmožnosti!$D$26=2)+(Profili!AB14=1)*(Zmožnosti!$D$27=2)+(Profili!AC14=1)*(Zmožnosti!$D$28=2)+(Profili!AD14=1)*(Zmožnosti!$D$29=2)+(Profili!AE14=1)*(Zmožnosti!$D$30=2)+(Profili!AF14=1)*(Zmožnosti!$D$31=2) -> 2 | F14: =(Profili!R14=1)*(Zmožnosti!$D$17=3)+(Profili!S14=1)*(Zmožnosti!$D$18=3)+(Profili!T14=1)*(Zmožnosti!$D$19=3)+(Profili!U14=1)*(Zmožnosti!$D$20=3)+(Profili!V14=1)*(Zmožnosti!$D$21=3)+(Profili!W14=1)*(Zmožnosti!$D$22=3)+(Profili!X14=1)*(Zmožnosti!$D$23=3)+(Profili!Y14=1)*(Zmožnosti!$D$24=3)+(Profili!Z14=1)*(Zmožnosti!$D$25=3)+(Profili!AA14=1)*(Zmožnosti!$D$26=3)+(Profili!AB14=1)*(Zmožnosti!$D$27=3)+(Profili!AC14=1)*(Zmožnosti!$D$28=3)+(Profili!AD14=1)*(Zmožnosti!$D$29=3)+(Profili!AE14=1)*(Zmožnosti!$D$30=3)+(Profili!AF14=1)*(Zmožnosti!$D$31=3) -> 3 | G14: =(Profili!R14=1)*(Zmožnosti!$D$17=99)+(Profili!S14=1)*(Zmožnosti!$D$18=99)+(Profili!T14=1)*(Zmožnosti!$D$19=99)+(Profili!U14=1)*(Zmožnosti!$D$20=99)+(Profili!V14=1)*(Zmožnosti!$D$21=99)+(Profili!W14=1)*(Zmožnosti!$D$22=99)+(Profili!X14=1)*(Zmožnosti!$D$23=99)+(Profili!Y14=1)*(Zmožnosti!$D$24=99)+(Profili!Z14=1)*(Zmožnosti!$D$25=99)+(Profili!AA14=1)*(Zmožnosti!$D$26=99)+(Profili!AB14=1)*(Zmožnosti!$D$27=99)+(Profili!AC14=1)*(Zmožnosti!$D$28=99)+(Profili!AD14=1)*(Zmožnosti!$D$29=99)+(Profili!AE14=1)*(Zmožnosti!$D$30=99)+(Profili!AF14=1)*(Zmožnosti!$D$31=99) -> 0
A15: =Profili!B15 -> Pogostitve in slavja | B15: =_xlfn.TEXTJOIN(", ",TRUE(),IF(AND(Profili!R15=1,Zmožnosti!$D$17=2),"Mize",""),IF(AND(Profili!S15=1,Zmožnosti!$D$18=2),"Kuhinja",""),IF(AND(Profili!T15=1,Zmožnosti!$D$19=2),"Točilnica",""),IF(AND(Profili!U15=1,Zmožnosti!$D$20=2),"Pripravljena hrana",""),IF(AND(Profili!V15=1,Zmožnosti!$D$21=2),"Odpadki",""),IF(AND(Profili!W15=1,Zmožnosti!$D$22=2),"Telefonska naročila",""),IF(AND(Profili!X15=1,Zmožnosti!$D$23=2),"Rezervacije",""),IF(AND(Profili!Y15=1,Zmožnosti!$D$24=2),"Dostava",""),IF(AND(Profili!Z15=1,Zmožnosti!$D$25=2),"QR meni",""),IF(AND(Profili!AA15=1,Zmožnosti!$D$26=2),"Večhodni meniji",""),IF(AND(Profili!AB15=1,Zmožnosti!$D$27=2),"Dogodki",""),IF(AND(Profili!AC15=1,Zmožnosti!$D$28=2),"Prenosi zaloge",""),IF(AND(Profili!AD15=1,Zmožnosti!$D$29=2),"Kavcije/boni/žetoni",""),IF(AND(Profili!AE15=1,Zmožnosti!$D$30=2),"Simulacija",""),IF(AND(Profili!AF15=1,Zmožnosti!$D$31=2),"Samopostrežna ponudba","")) -> Mize, Kuhinja, Točilnica | C15: =_xlfn.TEXTJOIN(", ",TRUE(),IF(AND(Profili!R15=1,Zmožnosti!$D$17=3),"Mize",""),IF(AND(Profili!S15=1,Zmožnosti!$D$18=3),"Kuhinja",""),IF(AND(Profili!T15=1,Zmožnosti!$D$19=3),"Točilnica",""),IF(AND(Profili!U15=1,Zmožnosti!$D$20=3),"Pripravljena hrana",""),IF(AND(Profili!V15=1,Zmožnosti!$D$21=3),"Odpadki",""),IF(AND(Profili!W15=1,Zmožnosti!$D$22=3),"Telefonska naročila",""),IF(AND(Profili!X15=1,Zmožnosti!$D$23=3),"Rezervacije",""),IF(AND(Profili!Y15=1,Zmožnosti!$D$24=3),"Dostava",""),IF(AND(Profili!Z15=1,Zmožnosti!$D$25=3),"QR meni",""),IF(AND(Profili!AA15=1,Zmožnosti!$D$26=3),"Večhodni meniji",""),IF(AND(Profili!AB15=1,Zmožnosti!$D$27=3),"Dogodki",""),IF(AND(Profili!AC15=1,Zmožnosti!$D$28=3),"Prenosi zaloge",""),IF(AND(Profili!AD15=1,Zmožnosti!$D$29=3),"Kavcije/boni/žetoni",""),IF(AND(Profili!AE15=1,Zmožnosti!$D$30=3),"Simulacija",""),IF(AND(Profili!AF15=1,Zmožnosti!$D$31=3),"Samopostrežna ponudba","")) -> Rezervacije, Večhodni meniji, Dogodki, Prenosi zaloge | D15: =_xlfn.TEXTJOIN(", ",TRUE(),IF(AND(Profili!R15=1,Zmožnosti!$D$17=99),"Mize",""),IF(AND(Profili!S15=1,Zmožnosti!$D$18=99),"Kuhinja",""),IF(AND(Profili!T15=1,Zmožnosti!$D$19=99),"Točilnica",""),IF(AND(Profili!U15=1,Zmožnosti!$D$20=99),"Pripravljena hrana",""),IF(AND(Profili!V15=1,Zmožnosti!$D$21=99),"Odpadki",""),IF(AND(Profili!W15=1,Zmožnosti!$D$22=99),"Telefonska naročila",""),IF(AND(Profili!X15=1,Zmožnosti!$D$23=99),"Rezervacije",""),IF(AND(Profili!Y15=1,Zmožnosti!$D$24=99),"Dostava",""),IF(AND(Profili!Z15=1,Zmožnosti!$D$25=99),"QR meni",""),IF(AND(Profili!AA15=1,Zmožnosti!$D$26=99),"Večhodni meniji",""),IF(AND(Profili!AB15=1,Zmožnosti!$D$27=99),"Dogodki",""),IF(AND(Profili!AC15=1,Zmožnosti!$D$28=99),"Prenosi zaloge",""),IF(AND(Profili!AD15=1,Zmožnosti!$D$29=99),"Kavcije/boni/žetoni",""),IF(AND(Profili!AE15=1,Zmožnosti!$D$30=99),"Simulacija",""),IF(AND(Profili!AF15=1,Zmožnosti!$D$31=99),"Samopostrežna ponudba","")) | E15: =(Profili!R15=1)*(Zmožnosti!$D$17=2)+(Profili!S15=1)*(Zmožnosti!$D$18=2)+(Profili!T15=1)*(Zmožnosti!$D$19=2)+(Profili!U15=1)*(Zmožnosti!$D$20=2)+(Profili!V15=1)*(Zmožnosti!$D$21=2)+(Profili!W15=1)*(Zmožnosti!$D$22=2)+(Profili!X15=1)*(Zmožnosti!$D$23=2)+(Profili!Y15=1)*(Zmožnosti!$D$24=2)+(Profili!Z15=1)*(Zmožnosti!$D$25=2)+(Profili!AA15=1)*(Zmožnosti!$D$26=2)+(Profili!AB15=1)*(Zmožnosti!$D$27=2)+(Profili!AC15=1)*(Zmožnosti!$D$28=2)+(Profili!AD15=1)*(Zmožnosti!$D$29=2)+(Profili!AE15=1)*(Zmožnosti!$D$30=2)+(Profili!AF15=1)*(Zmožnosti!$D$31=2) -> 3 | F15: =(Profili!R15=1)*(Zmožnosti!$D$17=3)+(Profili!S15=1)*(Zmožnosti!$D$18=3)+(Profili!T15=1)*(Zmožnosti!$D$19=3)+(Profili!U15=1)*(Zmožnosti!$D$20=3)+(Profili!V15=1)*(Zmožnosti!$D$21=3)+(Profili!W15=1)*(Zmožnosti!$D$22=3)+(Profili!X15=1)*(Zmožnosti!$D$23=3)+(Profili!Y15=1)*(Zmožnosti!$D$24=3)+(Profili!Z15=1)*(Zmožnosti!$D$25=3)+(Profili!AA15=1)*(Zmožnosti!$D$26=3)+(Profili!AB15=1)*(Zmožnosti!$D$27=3)+(Profili!AC15=1)*(Zmožnosti!$D$28=3)+(Profili!AD15=1)*(Zmožnosti!$D$29=3)+(Profili!AE15=1)*(Zmožnosti!$D$30=3)+(Profili!AF15=1)*(Zmožnosti!$D$31=3) -> 4 | G15: =(Profili!R15=1)*(Zmožnosti!$D$17=99)+(Profili!S15=1)*(Zmožnosti!$D$18=99)+(Profili!T15=1)*(Zmožnosti!$D$19=99)+(Profili!U15=1)*(Zmožnosti!$D$20=99)+(Profili!V15=1)*(Zmožnosti!$D$21=99)+(Profili!W15=1)*(Zmožnosti!$D$22=99)+(Profili!X15=1)*(Zmožnosti!$D$23=99)+(Profili!Y15=1)*(Zmožnosti!$D$24=99)+(Profili!Z15=1)*(Zmožnosti!$D$25=99)+(Profili!AA15=1)*(Zmožnosti!$D$26=99)+(Profili!AB15=1)*(Zmožnosti!$D$27=99)+(Profili!AC15=1)*(Zmožnosti!$D$28=99)+(Profili!AD15=1)*(Zmožnosti!$D$29=99)+(Profili!AE15=1)*(Zmožnosti!$D$30=99)+(Profili!AF15=1)*(Zmožnosti!$D$31=99) -> 0
